File: data/ETO_IV_metal_9T.dat
[Header]
;Copyright 2015, Quantum Design, Inc. All rights reserved.
FILEOPENTIME, 0.0, ,8/27/2024 8:42:58 PM
BYAPP, Electrical Transport Option, Release 1.2.0 Build 0
INFO, APPNAME, ETOption, Release 1.2.0 Build 0
TITLE, Electrical Transport Option (CAN)
STARTUPAXIS, X, 2, LINEAR, AUTO
STARTUPAXIS, Y1, 7, LINEAR, AUTO
STARTUPAXIS, Y2, 9, LINEAR, AUTO
STARTUPAXIS, Y3, 27, LINEAR, AUTO
STARTUPAXIS, Y4, 29, LINEAR, AUTO
TIMEMODE, SECONDS, RELATIVE
PLOT_APPEARANCE, ALL, HORZ_GRID_ON, VERT_GRID_ON,,AUTO_LINES
RECORDS, ALL_RECORDS
DATATYPE, COMMENT, 1
[Data]
Comment,Time Stamp (s),Temperature (K),Field (Oe),Sample Position (deg),Chamber Pressure (Torr),Resistance Ch1 (Ohms),Resistance Std. Dev. Ch1 (Ohms),Phase Angle Ch1 (deg),I-V Current Ch1 (mA),I-V Voltage Ch1 (V),Frequency Ch1 (Hz),Averaging Time Ch1 (s),AC Current Ch1 (mA),DC Current Ch1 (mA),Voltage Ampl Ch1 (V),In Phase Voltage Ampl Ch1 (V),Quadrature Voltage Ch1 (V),AC Voltage Ch1 (V),DC Voltage Ch1 (V),Current Ampl Ch1 (mA),In Phase Current Ch1 (mA),Quadrature Current Ch1 (mA),Gain Ch1,2nd Harmonic Ch1 (dB),3rd Harmonic Ch1 (dB),Resistance Ch2 (Ohms),Resistance Std. Dev. Ch2 (Ohms),Phase Angle Ch2 (deg),I-V Current Ch2 (mA),I-V Voltage Ch2 (V),Frequency Ch2 (Hz),Averaging Time Ch2 (s),AC Current Ch2 (mA),DC Current Ch2 (mA),Voltage Ampl Ch2 (V),In Phase Voltage Ampl Ch2 (V),Quadrature Voltage Ch2 (V),AC Voltage Ch2 (V),DC Voltage Ch2 (V),Current Ampl Ch2 (mA),In Phase Current Ch2 (mA),Quadrature Current Ch2 (mA),Gain Ch2,2nd Harmonic Ch2 (dB),3rd Harmonic Ch2 (dB),ETO Status Code,ETO Measurement Mode,Temperature Status (code),Field Status (code),Chamber Status (code),ETO Channel 1,ETO Channel 2,ETO Channel 3,ETO Channel 4,ETO Channel 5,ETO Channel 6,ETO Channel 7,ETO Channel 8,ETO Channel 9,ETO Channel 10,ETO Channel 11,ETO Channel 12,ETO Channel 13,ETO Channel 14,ETO Channel 15,ETO Channel 16

,3933952865.66236,390.009307861328,89999.75,,,,,,0,-0.0005488221,,0.98304,0,0,,,,,,,,,1,,,,,,,,,,,,,,,,,,,,,,,,,1,4,1,,,,,,,,,,,,,,,,
,3933952865.66452,390.009307861328,89999.75,,,,,,1.054584,0.001509261,,0.98304,0,0,,,,,,,,,1,,,,,,,,,,,,,,,,,,,,,,,,,1,4,1,,,,,,,,,,,,,,,,
,3933952865.66668,390.009307861328,89999.75,,,,,,2.109168,0.002195288,,0.98304,0,0,,,,,,,,,1,,,,,,,,,,,,,,,,,,,,,,,,,1,4,1,,,,,,,,,,,,,,,,
,3933952865.66884,390.009307861328,89999.75,,,,,,3.164091,0.003601645,,0.98304,0,0,,,,,,,,,1,,,,,,,,,,,,,,,,,,,,,,,,,1,4,1,,,,,,,,,,,,,,,,
,3933952865.671,390.009307861328,89999.75,,,,,,4.218675,0.005865536,,0.98304,0,0,,,,,,,,,1,,,,,,,,,,,,,,,,,,,,,,,,,1,4,1,,,,,,,,,,,,,,,,
,3933952865.67316,390.009307861328,89999.75,,,,,,5.273599,0.006482961,,0.98304,0,0,,,,,,,,,1,,,,,,,,,,,,,,,,,,,,,,,,,1,4,1,,,,,,,,,,,,,,,,
,3933952865.67532,390.009307861328,89999.75,,,,,,6.328183,0.008300934,,0.98304,0,0,,,,,,,,,1,,,,,,,,,,,,,,,,,,,,,,,,,1,4,1,,,,,,,,,,,,,,,,
,3933952865.67748,390.009307861328,89999.75,,,,,,7.382767,0.00919277,,0.98304,0,0,,,,,,,,,1,,,,,,,,,,,,,,,,,,,,,,,,,1,4,1,,,,,,,,,,,,,,,,
,3933952865.67964,390.009307861328,89999.75,,,,,,8.43769,0.01029041,,0.98304,0,0,,,,,,,,,1,,,,,,,,,,,,,,,,,,,,,,,,,1,4,1,,,,,,,,,,,,,,,,
,3933952865.6818,390.009307861328,89999.75,,,,,,9.492273,0.01166247,,0.98304,0,0,,,,,,,,,1,,,,,,,,,,,,,,,,,,,,,,,,,1,4,1,,,,,,,,,,,,,,,,
,3933952865.68396,390.009307861328,89999.75,,,,,,9.453278,0.0124514,,0.98304,0,0,,,,,,,,,1,,,,,,,,,,,,,,,,,,,,,,,,,1,4,1,,,,,,,,,,,,,,,,
,3933952865.68612,390.009307861328,89999.75,,,,,,8.398694,0.01083924,,0.98304,0,0,,,,,,,,,1,,,,,,,,,,,,,,,,,,,,,,,,,1,4,1,,,,,,,,,,,,,,,,
,3933952865.68828,390.009307861328,89999.75,,,,,,7.343771,0.009467182,,0.98304,0,0,,,,,,,,,1,,,,,,,,,,,,,,,,,,,,,,,,,1,4,1,,,,,,,,,,,,,,,,
,3933952865.69044,390.009307861328,89999.75,,,,,,6.289186,0.00867825,,0.98304,0,0,,,,,,,,,1,,,,,,,,,,,,,,,,,,,,,,,,,1,4,1,,,,,,,,,,,,,,,,
,3933952865.6926,390.009307861328,89999.75,,,,,,5.234263,0.006791674,,0.98304,0,0,,,,,,,,,1,,,,,,,,,,,,,,,,,,,,,,,,,1,4,1,,,,,,,,,,,,,,,,
,3933952865.69476,390.009307861328,89999.75,,,,,,4.179679,0.005488221,,0.98304,0,0,,,,,,,,,1,,,,,,,,,,,,,,,,,,,,,,,,,1,4,1,,,,,,,,,,,,,,,,
,3933952865.69692,390.009307861328,89999.75,,,,,,3.125095,0.003327234,,0.98304,0,0,,,,,,,,,1,,,,,,,,,,,,,,,,,,,,,,,,,1,4,1,,,,,,,,,,,,,,,,
,3933952865.69908,390.009307861328,89999.75,,,,,,2.070172,0.003155727,,0.98304,0,0,,,,,,,,,1,,,,,,,,,,,,,,,,,,,,,,,,,1,4,1,,,,,,,,,,,,,,,,
,3933952865.70124,390.009307861328,89999.75,,,,,,1.015588,0.001509261,,0.98304,0,0,,,,,,,,,1,,,,,,,,,,,,,,,,,,,,,,,,,1,4,1,,,,,,,,,,,,,,,,
,3933952865.7034,390.009307861328,89999.75,,,,,,-0.03899587,-0.0002744111,,0.98304,0,0,,,,,,,,,1,,,,,,,,,,,,,,,,,,,,,,,,,1,4,1,,,,,,,,,,,,,,,,
,3933952865.70556,390.009307861328,89999.75,,,,,,-1.09358,-0.002332494,,0.98304,0,0,,,,,,,,,1,,,,,,,,,,,,,,,,,,,,,,,,,1,4,1,,,,,,,,,,,,,,,,
,3933952865.70772,390.009307861328,89999.75,,,,,,-2.148503,-0.003430138,,0.98304,0,0,,,,,,,,,1,,,,,,,,,,,,,,,,,,,,,,,,,1,4,1,,,,,,,,,,,,,,,,
,3933952865.70988,390.009307861328,89999.75,,,,,,-3.203087,-0.004767892,,0.98304,0,0,,,,,,,,,1,,,,,,,,,,,,,,,,,,,,,,,,,1,4,1,,,,,,,,,,,,,,,,
,3933952865.71204,390.009307861328,89999.75,,,,,,-4.257671,-0.005694029,,0.98304,0,0,,,,,,,,,1,,,,,,,,,,,,,,,,,,,,,,,,,1,4,1,,,,,,,,,,,,,,,,
,3933952865.7142,390.009307861328,89999.75,,,,,,-5.312594,-0.00819803,,0.98304,0,0,,,,,,,,,1,,,,,,,,,,,,,,,,,,,,,,,,,1,4,1,,,,,,,,,,,,,,,,
,3933952865.71636,390.009307861328,89999.75,,,,,,-6.367178,-0.009261373,,0.98304,0,0,,,,,,,,,1,,,,,,,,,,,,,,,,,,,,,,,,,1,4,1,,,,,,,,,,,,,,,,
,3933952865.71852,390.009307861328,89999.75,,,,,,-7.422101,-0.01077063,,0.98304,0,0,,,,,,,,,1,,,,,,,,,,,,,,,,,,,,,,,,,1,4,1,,,,,,,,,,,,,,,,
,3933952865.72068,390.009307861328,89999.75,,,,,,-8.476686,-0.01190258,,0.98304,0,0,,,,,,,,,1,,,,,,,,,,,,,,,,,,,,,,,,,1,4,1,,,,,,,,,,,,,,,,
,3933952865.72284,390.009307861328,89999.75,,,,,,-9.53127,-0.01313743,,0.98304,0,0,,,,,,,,,1,,,,,,,,,,,,,,,,,,,,,,,,,1,4,1,,,,,,,,,,,,,,,,
,3933952865.725,390.009307861328,89999.75,,,,,,-9.414282,-0.01348044,,0.98304,0,0,,,,,,,,,1,,,,,,,,,,,,,,,,,,,,,,,,,1,4,1,,,,,,,,,,,,,,,,
,3933952865.72716,390.009307861328,89999.75,,,,,,-8.359359,-0.0123142,,0.98304,0,0,,,,,,,,,1,,,,,,,,,,,,,,,,,,,,,,,,,1,4,1,,,,,,,,,,,,,,,,
,3933952865.72932,390.009307861328,89999.75,,,,,,-7.304775,-0.01025611,,0.98304,0,0,,,,,,,,,1,,,,,,,,,,,,,,,,,,,,,,,,,1,4,1,,,,,,,,,,,,,,,,
,3933952865.73148,390.009307861328,89999.75,,,,,,-6.250191,-0.008643948,,0.98304,0,0,,,,,,,,,1,,,,,,,,,,,,,,,,,,,,,,,,,1,4,1,,,,,,,,,,,,,,,,
,3933952865.73364,390.009307861328,89999.75,,,,,,-5.195268,-0.008163729,,0.98304,0,0,,,,,,,,,1,,,,,,,,,,,,,,,,,,,,,,,,,1,4,1,,,,,,,,,,,,,,,,
,3933952865.7358,390.009307861328,89999.75,,,,,,-4.140684,-0.006242851,,0.98304,0,0,,,,,,,,,1,,,,,,,,,,,,,,,,,,,,,,,,,1,4,1,,,,,,,,,,,,,,,,
,3933952865.73796,390.009307861328,89999.75,,,,,,-3.08576,-0.004116166,,0.98304,0,0,,,,,,,,,1,,,,,,,,,,,,,,,,,,,,,,,,,1,4,1,,,,,,,,,,,,,,,,
,3933952865.74012,390.009307861328,89999.75,,,,,,-2.031176,-0.002881316,,0.98304,0,0,,,,,,,,,1,,,,,,,,,,,,,,,,,,,,,,,,,1,4,1,,,,,,,,,,,,,,,,
,3933952865.74228,390.009307861328,89999.75,,,,,,-0.9765923,-0.001955179,,0.98304,0,0,,,,,,,,,1,,,,,,,,,,,,,,,,,,,,,,,,,1,4,1,,,,,,,,,,,,,,,,
,3933953905.73548,334.678283691406,89999.59375,,,,,,0.1169876,0.0007889318,,0.98304,0,0,,,,,,,,,1,,,,,,,,,,,,,,,,,,,,,,,,,1,4,1,,,,,,,,,,,,,,,,
,3933953905.73764,334.678283691406,89999.59375,,,,,,1.171911,0.001200548,,0.98304,0,0,,,,,,,,,1,,,,,,,,,,,,,,,,,,,,,,,,,1,4,1,,,,,,,,,,,,,,,,
,3933953905.7398,334.678283691406,89999.59375,,,,,,2.226495,0.003190028,,0.98304,0,0,,,,,,,,,1,,,,,,,,,,,,,,,,,,,,,,,,,1,4,1,,,,,,,,,,,,,,,,
,3933953905.74196,334.678283691406,89999.59375,,,,,,3.281079,0.004424878,,0.98304,0,0,,,,,,,,,1,,,,,,,,,,,,,,,,,,,,,,,,,1,4,1,,,,,,,,,,,,,,,,
,3933953905.74412,334.678283691406,89999.59375,,,,,,4.336002,0.004356275,,0.98304,0,0,,,,,,,,,1,,,,,,,,,,,,,,,,,,,,,,,,,1,4,1,,,,,,,,,,,,,,,,
,3933953905.74628,334.678283691406,89999.59375,,,,,,5.390586,0.006860276,,0.98304,0,0,,,,,,,,,1,,,,,,,,,,,,,,,,,,,,,,,,,1,4,1,,,,,,,,,,,,,,,,
,3933953905.74844,334.678283691406,89999.59375,,,,,,6.445509,0.006414359,,0.98304,0,0,,,,,,,,,1,,,,,,,,,,,,,,,,,,,,,,,,,1,4,1,,,,,,,,,,,,,,,,
,3933953905.7506,334.678283691406,89999.59375,,,,,,7.500093,0.008095126,,0.98304,0,0,,,,,,,,,1,,,,,,,,,,,,,,,,,,,,,,,,,1,4,1,,,,,,,,,,,,,,,,
,3933953905.75276,334.678283691406,89999.59375,,,,,,8.554677,0.008918359,,0.98304,0,0,,,,,,,,,1,,,,,,,,,,,,,,,,,,,,,,,,,1,4,1,,,,,,,,,,,,,,,,
,3933953905.75492,334.678283691406,89999.59375,,,,,,9.6096,0.01056483,,0.98304,0,0,,,,,,,,,1,,,,,,,,,,,,,,,,,,,,,,,,,1,4,1,,,,,,,,,,,,,,,,
,3933953905.75708,334.678283691406,89999.59375,,,,,,9.335951,0.01183398,,0.98304,0,0,,,,,,,,,1,,,,,,,,,,,,,,,,,,,,,,,,,1,4,1,,,,,,,,,,,,,,,,
,3933953905.75924,334.678283691406,89999.59375,,,,,,8.281367,0.009741592,,0.98304,0,0,,,,,,,,,1,,,,,,,,,,,,,,,,,,,,,,,,,1,4,1,,,,,,,,,,,,,,,,
,3933953905.7614,334.678283691406,89999.59375,,,,,,7.226783,0.009638689,,0.98304,0,0,,,,,,,,,1,,,,,,,,,,,,,,,,,,,,,,,,,1,4,1,,,,,,,,,,,,,,,,
,3933953905.76356,334.678283691406,89999.59375,,,,,,6.17186,0.007066085,,0.98304,0,0,,,,,,,,,1,,,,,,,,,,,,,,,,,,,,,,,,,1,4,1,,,,,,,,,,,,,,,,
,3933953905.76572,334.678283691406,89999.59375,,,,,,5.117276,0.005282413,,0.98304,0,0,,,,,,,,,1,,,,,,,,,,,,,,,,,,,,,,,,,1,4,1,,,,,,,,,,,,,,,,
,3933953905.76788,334.678283691406,89999.59375,,,,,,4.062353,0.004459179,,0.98304,0,0,,,,,,,,,1,,,,,,,,,,,,,,,,,,,,,,,,,1,4,1,,,,,,,,,,,,,,,,
,3933953905.77004,334.678283691406,89999.59375,,,,,,3.007769,0.003430138,,0.98304,0,0,,,,,,,,,1,,,,,,,,,,,,,,,,,,,,,,,,,1,4,1,,,,,,,,,,,,,,,,
,3933953905.7722,334.678283691406,89999.59375,,,,,,1.953185,0.001543562,,0.98304,0,0,,,,,,,,,1,,,,,,,,,,,,,,,,,,,,,,,,,1,4,1,,,,,,,,,,,,,,,,
,3933953905.77436,334.678283691406,89999.59375,,,,,,0.8982615,0.001715069,,0.98304,0,0,,,,,,,,,1,,,,,,,,,,,,,,,,,,,,,,,,,1,4,1,,,,,,,,,,,,,,,,
,3933953905.77652,334.678283691406,89999.59375,,,,,,-0.1559835,-0.0006860276,,0.98304,0,0,,,,,,,,,1,,,,,,,,,,,,,,,,,,,,,,,,,1,4,1,,,,,,,,,,,,,,,,
,3933953905.77868,334.678283691406,89999.59375,,,,,,-1.210907,-0.002126686,,0.98304,0,0,,,,,,,,,1,,,,,,,,,,,,,,,,,,,,,,,,,1,4,1,,,,,,,,,,,,,,,,
,3933953905.78084,334.678283691406,89999.59375,,,,,,-2.265491,-0.001715069,,0.98304,0,0,,,,,,,,,1,,,,,,,,,,,,,,,,,,,,,,,,,1,4,1,,,,,,,,,,,,,,,,
,3933953905.783,334.678283691406,89999.59375,,,,,,-3.320414,-0.004253371,,0.98304,0,0,,,,,,,,,1,,,,,,,,,,,,,,,,,,,,,,,,,1,4,1,,,,,,,,,,,,,,,,
,3933953905.78516,334.678283691406,89999.59375,,,,,,-4.374998,-0.004870796,,0.98304,0,0,,,,,,,,,1,,,,,,,,,,,,,,,,,,,,,,,,,1,4,1,,,,,,,,,,,,,,,,
,3933953905.78732,334.678283691406,89999.59375,,,,,,-5.429582,-0.007477701,,0.98304,0,0,,,,,,,,,1,,,,,,,,,,,,,,,,,,,,,,,,,1,4,1,,,,,,,,,,,,,,,,
,3933953905.78948,334.678283691406,89999.59375,,,,,,-6.484505,-0.007306194,,0.98304,0,0,,,,,,,,,1,,,,,,,,,,,,,,,,,,,,,,,,,1,4,1,,,,,,,,,,,,,,,,
,3933953905.79164,334.678283691406,89999.59375,,,,,,-7.539089,-0.008986962,,0.98304,0,0,,,,,,,,,1,,,,,,,,,,,,,,,,,,,,,,,,,1,4,1,,,,,,,,,,,,,,,,
,3933953905.7938,334.678283691406,89999.59375,,,,,,-8.594012,-0.01070203,,0.98304,0,0,,,,,,,,,1,,,,,,,,,,,,,,,,,,,,,,,,,1,4,1,,,,,,,,,,,,,,,,
,3933953905.79596,334.678283691406,89999.59375,,,,,,-9.648597,-0.01138806,,0.98304,0,0,,,,,,,,,1,,,,,,,,,,,,,,,,,,,,,,,,,1,4,1,,,,,,,,,,,,,,,,
,3933953905.79812,334.678283691406,89999.59375,,,,,,-9.296955,-0.01107935,,0.98304,0,0,,,,,,,,,1,,,,,,,,,,,,,,,,,,,,,,,,,1,4,1,,,,,,,,,,,,,,,,
,3933953905.80028,334.678283691406,89999.59375,,,,,,-8.242372,-0.009810195,,0.98304,0,0,,,,,,,,,1,,,,,,,,,,,,,,,,,,,,,,,,,1,4,1,,,,,,,,,,,,,,,,
,3933953905.80244,334.678283691406,89999.59375,,,,,,-7.187448,-0.008609647,,0.98304,0,0,,,,,,,,,1,,,,,,,,,,,,,,,,,,,,,,,,,1,4,1,,,,,,,,,,,,,,,,
,3933953905.8046,334.678283691406,89999.59375,,,,,,-6.132864,-0.007306194,,0.98304,0,0,,,,,,,,,1,,,,,,,,,,,,,,,,,,,,,,,,,1,4,1,,,,,,,,,,,,,,,,
,3933953905.80676,334.678283691406,89999.59375,,,,,,-5.07828,-0.00545392,,0.98304,0,0,,,,,,,,,1,,,,,,,,,,,,,,,,,,,,,,,,,1,4,1,,,,,,,,,,,,,,,,
,3933953905.80892,334.678283691406,89999.59375,,,,,,-4.023357,-0.005145207,,0.98304,0,0,,,,,,,,,1,,,,,,,,,,,,,,,,,,,,,,,,,1,4,1,,,,,,,,,,,,,,,,
,3933953905.81108,334.678283691406,89999.59375,,,,,,-2.968773,-0.00421907,,0.98304,0,0,,,,,,,,,1,,,,,,,,,,,,,,,,,,,,,,,,,1,4,1,,,,,,,,,,,,,,,,
,3933953905.81324,334.678283691406,89999.59375,,,,,,-1.91385,-0.003087124,,0.98304,0,0,,,,,,,,,1,,,,,,,,,,,,,,,,,,,,,,,,,1,4,1,,,,,,,,,,,,,,,,
,3933953905.8154,334.678283691406,89999.59375,,,,,,-0.8592656,-0.000445918,,0.98304,0,0,,,,,,,,,1,,,,,,,,,,,,,,,,,,,,,,,,,1,4,1,,,,,,,,,,,,,,,,
,3933954962.32936,279.261169433594,89999.578125,,,,,,,,,0.98304,0,0,,,,,,,,,1,,,,,,,,,,,,,,,,,,,,,,,,,1,4,1,,,,,,,,,,,,,,,,
,3933954962.32936,279.261169433594,89999.578125,,,,,,,,,0.98304,0,0,,,,,,,,,1,,,,,,,,,,,,,,,,,,,,,,,,,1,4,1,,,,,,,,,,,,,,,,
,3933954962.32936,279.261169433594,89999.578125,,,,,,,,,0.98304,0,0,,,,,,,,,1,,,,,,,,,,,,,,,,,,,,,,,,,1,4,1,,,,,,,,,,,,,,,,
,3933954962.32936,279.261169433594,89999.578125,,,,,,,,,0.98304,0,0,,,,,,,,,1,,,,,,,,,,,,,,,,,,,,,,,,,1,4,1,,,,,,,,,,,,,,,,
,3933954962.32936,279.261169433594,89999.578125,,,,,,,,,0.98304,0,0,,,,,,,,,1,,,,,,,,,,,,,,,,,,,,,,,,,1,4,1,,,,,,,,,,,,,,,,
,3933954962.32936,279.261169433594,89999.578125,,,,,,,,,0.98304,0,0,,,,,,,,,1,,,,,,,,,,,,,,,,,,,,,,,,,1,4,1,,,,,,,,,,,,,,,,
,3933954962.32936,279.261169433594,89999.578125,,,,,,,,,0.98304,0,0,,,,,,,,,1,,,,,,,,,,,,,,,,,,,,,,,,,1,4,1,,,,,,,,,,,,,,,,
,3933954962.32936,279.261169433594,89999.578125,,,,,,,,,0.98304,0,0,,,,,,,,,1,,,,,,,,,,,,,,,,,,,,,,,,,1,4,1,,,,,,,,,,,,,,,,
,3933954962.32936,279.261169433594,89999.578125,,,,,,,,,0.98304,0,0,,,,,,,,,1,,,,,,,,,,,,,,,,,,,,,,,,,1,4,1,,,,,,,,,,,,,,,,
,3933954962.32936,279.261169433594,89999.578125,,,,,,,,,0.98304,0,0,,,,,,,,,1,,,,,,,,,,,,,,,,,,,,,,,,,1,4,1,,,,,,,,,,,,,,,,
,3933954962.32936,279.261169433594,89999.578125,,,,,,,,,0.98304,0,0,,,,,,,,,1,,,,,,,,,,,,,,,,,,,,,,,,,1,4,1,,,,,,,,,,,,,,,,
,3933954962.32936,279.261169433594,89999.578125,,,,,,,,,0.98304,0,0,,,,,,,,,1,,,,,,,,,,,,,,,,,,,,,,,,,1,4,1,,,,,,,,,,,,,,,,
,3933954962.32936,279.261169433594,89999.578125,,,,,,,,,0.98304,0,0,,,,,,,,,1,,,,,,,,,,,,,,,,,,,,,,,,,1,4,1,,,,,,,,,,,,,,,,
,3933954962.32936,279.261169433594,89999.578125,,,,,,,,,0.98304,0,0,,,,,,,,,1,,,,,,,,,,,,,,,,,,,,,,,,,1,4,1,,,,,,,,,,,,,,,,
,3933954962.32936,279.261169433594,89999.578125,,,,,,,,,0.98304,0,0,,,,,,,,,1,,,,,,,,,,,,,,,,,,,,,,,,,1,4,1,,,,,,,,,,,,,,,,
,3933954962.32936,279.261169433594,89999.578125,,,,,,,,,0.98304,0,0,,,,,,,,,1,,,,,,,,,,,,,,,,,,,,,,,,,1,4,1,,,,,,,,,,,,,,,,
,3933954962.32936,279.261169433594,89999.578125,,,,,,,,,0.98304,0,0,,,,,,,,,1,,,,,,,,,,,,,,,,,,,,,,,,,1,4,1,,,,,,,,,,,,,,,,
,3933954962.32936,279.261169433594,89999.578125,,,,,,,,,0.98304,0,0,,,,,,,,,1,,,,,,,,,,,,,,,,,,,,,,,,,1,4,1,,,,,,,,,,,,,,,,
,3933954962.32936,279.261169433594,89999.578125,,,,,,,,,0.98304,0,0,,,,,,,,,1,,,,,,,,,,,,,,,,,,,,,,,,,1,4,1,,,,,,,,,,,,,,,,
,3933954962.32936,279.261169433594,89999.578125,,,,,,,,,0.98304,0,0,,,,,,,,,1,,,,,,,,,,,,,,,,,,,,,,,,,1,4,1,,,,,,,,,,,,,,,,
,3933954962.32936,279.261169433594,89999.578125,,,,,,,,,0.98304,0,0,,,,,,,,,1,,,,,,,,,,,,,,,,,,,,,,,,,1,4,1,,,,,,,,,,,,,,,,
,3933954962.32936,279.261169433594,89999.578125,,,,,,,,,0.98304,0,0,,,,,,,,,1,,,,,,,,,,,,,,,,,,,,,,,,,1,4,1,,,,,,,,,,,,,,,,
,3933954962.32936,279.261169433594,89999.578125,,,,,,,,,0.98304,0,0,,,,,,,,,1,,,,,,,,,,,,,,,,,,,,,,,,,1,4,1,,,,,,,,,,,,,,,,
,3933954962.32936,279.261169433594,89999.578125,,,,,,,,,0.98304,0,0,,,,,,,,,1,,,,,,,,,,,,,,,,,,,,,,,,,1,4,1,,,,,,,,,,,,,,,,
,3933954962.32936,279.261169433594,89999.578125,,,,,,,,,0.98304,0,0,,,,,,,,,1,,,,,,,,,,,,,,,,,,,,,,,,,1,4,1,,,,,,,,,,,,,,,,
,3933954962.32936,279.261169433594,89999.578125,,,,,,,,,0.98304,0,0,,,,,,,,,1,,,,,,,,,,,,,,,,,,,,,,,,,1,4,1,,,,,,,,,,,,,,,,
,3933954962.32936,279.261169433594,89999.578125,,,,,,,,,0.98304,0,0,,,,,,,,,1,,,,,,,,,,,,,,,,,,,,,,,,,1,4,1,,,,,,,,,,,,,,,,
,3933954962.32936,279.261169433594,89999.578125,,,,,,,,,0.98304,0,0,,,,,,,,,1,,,,,,,,,,,,,,,,,,,,,,,,,1,4,1,,,,,,,,,,,,,,,,
,3933954962.32936,279.261169433594,89999.578125,,,,,,,,,0.98304,0,0,,,,,,,,,1,,,,,,,,,,,,,,,,,,,,,,,,,1,4,1,,,,,,,,,,,,,,,,
,3933954962.32936,279.261169433594,89999.578125,,,,,,,,,0.98304,0,0,,,,,,,,,1,,,,,,,,,,,,,,,,,,,,,,,,,1,4,1,,,,,,,,,,,,,,,,
,3933954962.32936,279.261169433594,89999.578125,,,,,,,,,0.98304,0,0,,,,,,,,,1,,,,,,,,,,,,,,,,,,,,,,,,,1,4,1,,,,,,,,,,,,,,,,
,3933954962.32936,279.261169433594,89999.578125,,,,,,,,,0.98304,0,0,,,,,,,,,1,,,,,,,,,,,,,,,,,,,,,,,,,1,4,1,,,,,,,,,,,,,,,,
,3933954962.32936,279.261169433594,89999.578125,,,,,,,,,0.98304,0,0,,,,,,,,,1,,,,,,,,,,,,,,,,,,,,,,,,,1,4,1,,,,,,,,,,,,,,,,
,3933954962.32936,279.261169433594,89999.578125,,,,,,,,,0.98304,0,0,,,,,,,,,1,,,,,,,,,,,,,,,,,,,,,,,,,1,4,1,,,,,,,,,,,,,,,,
,3933954962.32936,279.261169433594,89999.578125,,,,,,,,,0.98304,0,0,,,,,,,,,1,,,,,,,,,,,,,,,,,,,,,,,,,1,4,1,,,,,,,,,,,,,,,,
,3933954962.32936,279.261169433594,89999.578125,,,,,,,,,0.98304,0,0,,,,,,,,,1,,,,,,,,,,,,,,,,,,,,,,,,,1,4,1,,,,,,,,,,,,,,,,
,3933954962.32936,279.261169433594,89999.578125,,,,,,,,,0.98304,0,0,,,,,,,,,1,,,,,,,,,,,,,,,,,,,,,,,,,1,4,1,,,,,,,,,,,,,,,,
,3933954962.32936,279.261169433594,89999.578125,,,,,,,,,0.98304,0,0,,,,,,,,,1,,,,,,,,,,,,,,,,,,,,,,,,,1,4,1,,,,,,,,,,,,,,,,
,3933956093.28016,223.803161621094,89999.8203125,,,,,,0.351302,-0.0003087124,,0.98304,0,0,,,,,,,,,1,,,,,,,,,,,,,,,,,,,,,,,,,1,4,1,,,,,,,,,,,,,,,,
,3933956093.28232,223.803161621094,89999.8203125,,,,,,1.406225,0.0008575345,,0.98304,0,0,,,,,,,,,1,,,,,,,,,,,,,,,,,,,,,,,,,1,4,1,,,,,,,,,,,,,,,,
,3933956093.28448,223.803161621094,89999.8203125,,,,,,2.460809,0.001474959,,0.98304,0,0,,,,,,,,,1,,,,,,,,,,,,,,,,,,,,,,,,,1,4,1,,,,,,,,,,,,,,,,
,3933956093.28664,223.803161621094,89999.8203125,,,,,,3.515732,0.003430138,,0.98304,0,0,,,,,,,,,1,,,,,,,,,,,,,,,,,,,,,,,,,1,4,1,,,,,,,,,,,,,,,,
,3933956093.28881,223.803161621094,89999.8203125,,,,,,4.570316,0.002709809,,0.98304,0,0,,,,,,,,,1,,,,,,,,,,,,,,,,,,,,,,,,,1,4,1,,,,,,,,,,,,,,,,
,3933956093.29096,223.803161621094,89999.8203125,,,,,,5.6249,0.004459179,,0.98304,0,0,,,,,,,,,1,,,,,,,,,,,,,,,,,,,,,,,,,1,4,1,,,,,,,,,,,,,,,,
,3933956093.29312,223.803161621094,89999.8203125,,,,,,6.679823,0.005179509,,0.98304,0,0,,,,,,,,,1,,,,,,,,,,,,,,,,,,,,,,,,,1,4,1,,,,,,,,,,,,,,,,
,3933956093.29528,223.803161621094,89999.8203125,,,,,,7.734407,0.005899838,,0.98304,0,0,,,,,,,,,1,,,,,,,,,,,,,,,,,,,,,,,,,1,4,1,,,,,,,,,,,,,,,,
,3933956093.29744,223.803161621094,89999.8203125,,,,,,8.78933,0.006414359,,0.98304,0,0,,,,,,,,,1,,,,,,,,,,,,,,,,,,,,,,,,,1,4,1,,,,,,,,,,,,,,,,
,3933956093.2996,223.803161621094,89999.8203125,,,,,,9.843915,0.008095126,,0.98304,0,0,,,,,,,,,1,,,,,,,,,,,,,,,,,,,,,,,,,1,4,1,,,,,,,,,,,,,,,,
,3933956093.30177,223.803161621094,89999.8203125,,,,,,9.101637,0.007855017,,0.98304,0,0,,,,,,,,,1,,,,,,,,,,,,,,,,,,,,,,,,,1,4,1,,,,,,,,,,,,,,,,
,3933956093.30392,223.803161621094,89999.8203125,,,,,,8.047052,0.006585865,,0.98304,0,0,,,,,,,,,1,,,,,,,,,,,,,,,,,,,,,,,,,1,4,1,,,,,,,,,,,,,,,,
,3933956093.30608,223.803161621094,89999.8203125,,,,,,6.99213,0.006414359,,0.98304,0,0,,,,,,,,,1,,,,,,,,,,,,,,,,,,,,,,,,,1,4,1,,,,,,,,,,,,,,,,
,3933956093.30824,223.803161621094,89999.8203125,,,,,,5.937546,0.0049737,,0.98304,0,0,,,,,,,,,1,,,,,,,,,,,,,,,,,,,,,,,,,1,4,1,,,,,,,,,,,,,,,,
,3933956093.3104,223.803161621094,89999.8203125,,,,,,4.882962,0.003327234,,0.98304,0,0,,,,,,,,,1,,,,,,,,,,,,,,,,,,,,,,,,,1,4,1,,,,,,,,,,,,,,,,
,3933956093.31256,223.803161621094,89999.8203125,,,,,,3.828038,0.002263891,,0.98304,0,0,,,,,,,,,1,,,,,,,,,,,,,,,,,,,,,,,,,1,4,1,,,,,,,,,,,,,,,,
,3933956093.31472,223.803161621094,89999.8203125,,,,,,2.773454,0.001577864,,0.98304,0,0,,,,,,,,,1,,,,,,,,,,,,,,,,,,,,,,,,,1,4,1,,,,,,,,,,,,,,,,
,3933956093.31689,223.803161621094,89999.8203125,,,,,,1.718531,-0.0001715069,,0.98304,0,0,,,,,,,,,1,,,,,,,,,,,,,,,,,,,,,,,,,1,4,1,,,,,,,,,,,,,,,,
,3933956093.31904,223.803161621094,89999.8203125,,,,,,0.6639471,0.0005831235,,0.98304,0,0,,,,,,,,,1,,,,,,,,,,,,,,,,,,,,,,,,,1,4,1,,,,,,,,,,,,,,,,
,3933956093.3212,223.803161621094,89999.8203125,,,,,,-0.3906369,-0.000445918,,0.98304,0,0,,,,,,,,,1,,,,,,,,,,,,,,,,,,,,,,,,,1,4,1,,,,,,,,,,,,,,,,
,3933956093.32336,223.803161621094,89999.8203125,,,,,,-1.445221,-0.001509261,,0.98304,0,0,,,,,,,,,1,,,,,,,,,,,,,,,,,,,,,,,,,1,4,1,,,,,,,,,,,,,,,,
,3933956093.32552,223.803161621094,89999.8203125,,,,,,-2.499805,-0.002949919,,0.98304,0,0,,,,,,,,,1,,,,,,,,,,,,,,,,,,,,,,,,,1,4,1,,,,,,,,,,,,,,,,
,3933956093.32768,223.803161621094,89999.8203125,,,,,,-3.554728,-0.003498741,,0.98304,0,0,,,,,,,,,1,,,,,,,,,,,,,,,,,,,,,,,,,1,4,1,,,,,,,,,,,,,,,,
,3933956093.32985,223.803161621094,89999.8203125,,,,,,-4.609312,-0.004287673,,0.98304,0,0,,,,,,,,,1,,,,,,,,,,,,,,,,,,,,,,,,,1,4,1,,,,,,,,,,,,,,,,
,3933956093.332,223.803161621094,89999.8203125,,,,,,-5.664236,-0.004939399,,0.98304,0,0,,,,,,,,,1,,,,,,,,,,,,,,,,,,,,,,,,,1,4,1,,,,,,,,,,,,,,,,
,3933956093.33416,223.803161621094,89999.8203125,,,,,,-6.71882,-0.006002742,,0.98304,0,0,,,,,,,,,1,,,,,,,,,,,,,,,,,,,,,,,,,1,4,1,,,,,,,,,,,,,,,,
,3933956093.33632,223.803161621094,89999.8203125,,,,,,-7.773404,-0.007580605,,0.98304,0,0,,,,,,,,,1,,,,,,,,,,,,,,,,,,,,,,,,,1,4,1,,,,,,,,,,,,,,,,
,3933956093.33848,223.803161621094,89999.8203125,,,,,,-8.828326,-0.008781154,,0.98304,0,0,,,,,,,,,1,,,,,,,,,,,,,,,,,,,,,,,,,1,4,1,,,,,,,,,,,,,,,,
,3933956093.34064,223.803161621094,89999.8203125,,,,,,-9.882911,-0.00795792,,0.98304,0,0,,,,,,,,,1,,,,,,,,,,,,,,,,,,,,,,,,,1,4,1,,,,,,,,,,,,,,,,
,3933956093.3428,223.803161621094,89999.8203125,,,,,,-9.062641,-0.008815455,,0.98304,0,0,,,,,,,,,1,,,,,,,,,,,,,,,,,,,,,,,,,1,4,1,,,,,,,,,,,,,,,,
,3933956093.34497,223.803161621094,89999.8203125,,,,,,-8.008057,-0.007889318,,0.98304,0,0,,,,,,,,,1,,,,,,,,,,,,,,,,,,,,,,,,,1,4,1,,,,,,,,,,,,,,,,
,3933956093.34712,223.803161621094,89999.8203125,,,,,,-6.953134,-0.006723071,,0.98304,0,0,,,,,,,,,1,,,,,,,,,,,,,,,,,,,,,,,,,1,4,1,,,,,,,,,,,,,,,,
,3933956093.34928,223.803161621094,89999.8203125,,,,,,-5.89855,-0.005042303,,0.98304,0,0,,,,,,,,,1,,,,,,,,,,,,,,,,,,,,,,,,,1,4,1,,,,,,,,,,,,,,,,
,3933956093.35144,223.803161621094,89999.8203125,,,,,,-4.843626,-0.004424878,,0.98304,0,0,,,,,,,,,1,,,,,,,,,,,,,,,,,,,,,,,,,1,4,1,,,,,,,,,,,,,,,,
,3933956093.3536,223.803161621094,89999.8203125,,,,,,-3.789042,-0.003807453,,0.98304,0,0,,,,,,,,,1,,,,,,,,,,,,,,,,,,,,,,,,,1,4,1,,,,,,,,,,,,,,,,
,3933956093.35576,223.803161621094,89999.8203125,,,,,,-2.734458,-0.00222959,,0.98304,0,0,,,,,,,,,1,,,,,,,,,,,,,,,,,,,,,,,,,1,4,1,,,,,,,,,,,,,,,,
,3933956093.35792,223.803161621094,89999.8203125,,,,,,-1.679535,-0.00198948,,0.98304,0,0,,,,,,,,,1,,,,,,,,,,,,,,,,,,,,,,,,,1,4,1,,,,,,,,,,,,,,,,
,3933956093.36008,223.803161621094,89999.8203125,,,,,,-0.6249512,-0.0009261373,,0.98304,0,0,,,,,,,,,1,,,,,,,,,,,,,,,,,,,,,,,,,1,4,1,,,,,,,,,,,,,,,,
,3933956661.31928,196.053131103516,89999.734375,,,,,,0.4686287,0.0009604387,,0.98304,0,0,,,,,,,,,1,,,,,,,,,,,,,,,,,,,,,,,,,1,4,1,,,,,,,,,,,,,,,,
,3933956661.32144,196.053131103516,89999.734375,,,,,,1.523213,0.0004116166,,0.98304,0,0,,,,,,,,,1,,,,,,,,,,,,,,,,,,,,,,,,,1,4,1,,,,,,,,,,,,,,,,
,3933956661.3236,196.053131103516,89999.734375,,,,,,2.578136,0.001303453,,0.98304,0,0,,,,,,,,,1,,,,,,,,,,,,,,,,,,,,,,,,,1,4,1,,,,,,,,,,,,,,,,
,3933956661.32576,196.053131103516,89999.734375,,,,,,3.63272,0.002298193,,0.98304,0,0,,,,,,,,,1,,,,,,,,,,,,,,,,,,,,,,,,,1,4,1,,,,,,,,,,,,,,,,
,3933956661.32792,196.053131103516,89999.734375,,,,,,4.687643,0.003498741,,0.98304,0,0,,,,,,,,,1,,,,,,,,,,,,,,,,,,,,,,,,,1,4,1,,,,,,,,,,,,,,,,
,3933956661.33008,196.053131103516,89999.734375,,,,,,5.742227,0.003773152,,0.98304,0,0,,,,,,,,,1,,,,,,,,,,,,,,,,,,,,,,,,,1,4,1,,,,,,,,,,,,,,,,
,3933956661.33224,196.053131103516,89999.734375,,,,,,6.796811,0.004630687,,0.98304,0,0,,,,,,,,,1,,,,,,,,,,,,,,,,,,,,,,,,,1,4,1,,,,,,,,,,,,,,,,
,3933956661.3344,196.053131103516,89999.734375,,,,,,7.851734,0.005282413,,0.98304,0,0,,,,,,,,,1,,,,,,,,,,,,,,,,,,,,,,,,,1,4,1,,,,,,,,,,,,,,,,
,3933956661.33656,196.053131103516,89999.734375,,,,,,8.906319,0.005934139,,0.98304,0,0,,,,,,,,,1,,,,,,,,,,,,,,,,,,,,,,,,,1,4,1,,,,,,,,,,,,,,,,
,3933956661.33872,196.053131103516,89999.734375,,,,,,9.961242,0.008232332,,0.98304,0,0,,,,,,,,,1,,,,,,,,,,,,,,,,,,,,,,,,,1,4,1,,,,,,,,,,,,,,,,
,3933956661.34088,196.053131103516,89999.734375,,,,,,8.98465,0.007374797,,0.98304,0,0,,,,,,,,,1,,,,,,,,,,,,,,,,,,,,,,,,,1,4,1,,,,,,,,,,,,,,,,
,3933956661.34304,196.053131103516,89999.734375,,,,,,7.929726,0.005762632,,0.98304,0,0,,,,,,,,,1,,,,,,,,,,,,,,,,,,,,,,,,,1,4,1,,,,,,,,,,,,,,,,
,3933956661.3452,196.053131103516,89999.734375,,,,,,6.875142,0.004253371,,0.98304,0,0,,,,,,,,,1,,,,,,,,,,,,,,,,,,,,,,,,,1,4,1,,,,,,,,,,,,,,,,
,3933956661.34736,196.053131103516,89999.734375,,,,,,5.820219,0.004356275,,0.98304,0,0,,,,,,,,,1,,,,,,,,,,,,,,,,,,,,,,,,,1,4,1,,,,,,,,,,,,,,,,
,3933956661.34952,196.053131103516,89999.734375,,,,,,4.765635,0.00397896,,0.98304,0,0,,,,,,,,,1,,,,,,,,,,,,,,,,,,,,,,,,,1,4,1,,,,,,,,,,,,,,,,
,3933956661.35168,196.053131103516,89999.734375,,,,,,3.711051,0.001955179,,0.98304,0,0,,,,,,,,,1,,,,,,,,,,,,,,,,,,,,,,,,,1,4,1,,,,,,,,,,,,,,,,
,3933956661.35384,196.053131103516,89999.734375,,,,,,2.656128,0.002538302,,0.98304,0,0,,,,,,,,,1,,,,,,,,,,,,,,,,,,,,,,,,,1,4,1,,,,,,,,,,,,,,,,
,3933956661.356,196.053131103516,89999.734375,,,,,,1.601544,0.001680768,,0.98304,0,0,,,,,,,,,1,,,,,,,,,,,,,,,,,,,,,,,,,1,4,1,,,,,,,,,,,,,,,,
,3933956661.35816,196.053131103516,89999.734375,,,,,,0.5466204,-0.0001372055,,0.98304,0,0,,,,,,,,,1,,,,,,,,,,,,,,,,,,,,,,,,,1,4,1,,,,,,,,,,,,,,,,
,3933956661.36032,196.053131103516,89999.734375,,,,,,-0.5076246,-0.0009261373,,0.98304,0,0,,,,,,,,,1,,,,,,,,,,,,,,,,,,,,,,,,,1,4,1,,,,,,,,,,,,,,,,
,3933956661.36248,196.053131103516,89999.734375,,,,,,-1.562548,-0.001715069,,0.98304,0,0,,,,,,,,,1,,,,,,,,,,,,,,,,,,,,,,,,,1,4,1,,,,,,,,,,,,,,,,
,3933956661.36464,196.053131103516,89999.734375,,,,,,-2.617132,-0.002504001,,0.98304,0,0,,,,,,,,,1,,,,,,,,,,,,,,,,,,,,,,,,,1,4,1,,,,,,,,,,,,,,,,
,3933956661.3668,196.053131103516,89999.734375,,,,,,-3.671716,-0.003738851,,0.98304,0,0,,,,,,,,,1,,,,,,,,,,,,,,,,,,,,,,,,,1,4,1,,,,,,,,,,,,,,,,
,3933956661.36896,196.053131103516,89999.734375,,,,,,-4.726639,-0.003155727,,0.98304,0,0,,,,,,,,,1,,,,,,,,,,,,,,,,,,,,,,,,,1,4,1,,,,,,,,,,,,,,,,
,3933956661.37112,196.053131103516,89999.734375,,,,,,-5.781223,-0.003395837,,0.98304,0,0,,,,,,,,,1,,,,,,,,,,,,,,,,,,,,,,,,,1,4,1,,,,,,,,,,,,,,,,
,3933956661.37328,196.053131103516,89999.734375,,,,,,-6.836146,-0.005899838,,0.98304,0,0,,,,,,,,,1,,,,,,,,,,,,,,,,,,,,,,,,,1,4,1,,,,,,,,,,,,,,,,
,3933956661.37544,196.053131103516,89999.734375,,,,,,-7.89073,-0.006277153,,0.98304,0,0,,,,,,,,,1,,,,,,,,,,,,,,,,,,,,,,,,,1,4,1,,,,,,,,,,,,,,,,
,3933956661.3776,196.053131103516,89999.734375,,,,,,-8.945314,-0.007649208,,0.98304,0,0,,,,,,,,,1,,,,,,,,,,,,,,,,,,,,,,,,,1,4,1,,,,,,,,,,,,,,,,
,3933956661.37976,196.053131103516,89999.734375,,,,,,-10.00024,-0.007820715,,0.98304,0,0,,,,,,,,,1,,,,,,,,,,,,,,,,,,,,,,,,,1,4,1,,,,,,,,,,,,,,,,
,3933956661.38192,196.053131103516,89999.734375,,,,,,-8.945314,-0.006380057,,0.98304,0,0,,,,,,,,,1,,,,,,,,,,,,,,,,,,,,,,,,,1,4,1,,,,,,,,,,,,,,,,
,3933956661.38408,196.053131103516,89999.734375,,,,,,-7.89073,-0.006654468,,0.98304,0,0,,,,,,,,,1,,,,,,,,,,,,,,,,,,,,,,,,,1,4,1,,,,,,,,,,,,,,,,
,3933956661.38624,196.053131103516,89999.734375,,,,,,-6.836146,-0.005728331,,0.98304,0,0,,,,,,,,,1,,,,,,,,,,,,,,,,,,,,,,,,,1,4,1,,,,,,,,,,,,,,,,
,3933956661.3884,196.053131103516,89999.734375,,,,,,-5.781223,-0.005351015,,0.98304,0,0,,,,,,,,,1,,,,,,,,,,,,,,,,,,,,,,,,,1,4,1,,,,,,,,,,,,,,,,
,3933956661.39056,196.053131103516,89999.734375,,,,,,-4.726639,-0.004836495,,0.98304,0,0,,,,,,,,,1,,,,,,,,,,,,,,,,,,,,,,,,,1,4,1,,,,,,,,,,,,,,,,
,3933956661.39272,196.053131103516,89999.734375,,,,,,-3.671716,-0.003533042,,0.98304,0,0,,,,,,,,,1,,,,,,,,,,,,,,,,,,,,,,,,,1,4,1,,,,,,,,,,,,,,,,
,3933956661.39488,196.053131103516,89999.734375,,,,,,-2.617132,-0.003018522,,0.98304,0,0,,,,,,,,,1,,,,,,,,,,,,,,,,,,,,,,,,,1,4,1,,,,,,,,,,,,,,,,
,3933956661.39704,196.053131103516,89999.734375,,,,,,-1.562548,-0.001303453,,0.98304,0,0,,,,,,,,,1,,,,,,,,,,,,,,,,,,,,,,,,,1,4,1,,,,,,,,,,,,,,,,
,3933956661.3992,196.053131103516,89999.734375,,,,,,-0.5076246,-0.0003773152,,0.98304,0,0,,,,,,,,,1,,,,,,,,,,,,,,,,,,,,,,,,,1,4,1,,,,,,,,,,,,,,,,
,3933957933.25569,140.639373779297,89999.6171875,,,,,,0.5859554,0.001440658,,0.98304,0,0,,,,,,,,,1,,,,,,,,,,,,,,,,,,,,,,,,,1,4,1,,,,,,,,,,,,,,,,
,3933957933.25785,140.639373779297,89999.6171875,,,,,,1.640539,0.0007889318,,0.98304,0,0,,,,,,,,,1,,,,,,,,,,,,,,,,,,,,,,,,,1,4,1,,,,,,,,,,,,,,,,
,3933957933.26001,140.639373779297,89999.6171875,,,,,,2.695123,0.0003430138,,0.98304,0,0,,,,,,,,,1,,,,,,,,,,,,,,,,,,,,,,,,,1,4,1,,,,,,,,,,,,,,,,
,3933957933.26217,140.639373779297,89999.6171875,,,,,,3.750047,0.002606905,,0.98304,0,0,,,,,,,,,1,,,,,,,,,,,,,,,,,,,,,,,,,1,4,1,,,,,,,,,,,,,,,,
,3933957933.26433,140.639373779297,89999.6171875,,,,,,4.804631,0.002366795,,0.98304,0,0,,,,,,,,,1,,,,,,,,,,,,,,,,,,,,,,,,,1,4,1,,,,,,,,,,,,,,,,
,3933957933.26649,140.639373779297,89999.6171875,,,,,,5.859554,0.002847015,,0.98304,0,0,,,,,,,,,1,,,,,,,,,,,,,,,,,,,,,,,,,1,4,1,,,,,,,,,,,,,,,,
,3933957933.26865,140.639373779297,89999.6171875,,,,,,6.914138,0.004184769,,0.98304,0,0,,,,,,,,,1,,,,,,,,,,,,,,,,,,,,,,,,,1,4,1,,,,,,,,,,,,,,,,
,3933957933.27081,140.639373779297,89999.6171875,,,,,,7.968722,0.004870796,,0.98304,0,0,,,,,,,,,1,,,,,,,,,,,,,,,,,,,,,,,,,1,4,1,,,,,,,,,,,,,,,,
,3933957933.27297,140.639373779297,89999.6171875,,,,,,9.023645,0.005110906,,0.98304,0,0,,,,,,,,,1,,,,,,,,,,,,,,,,,,,,,,,,,1,4,1,,,,,,,,,,,,,,,,
,3933957933.27513,140.639373779297,89999.6171875,,,,,,9.921906,0.005488221,,0.98304,0,0,,,,,,,,,1,,,,,,,,,,,,,,,,,,,,,,,,,1,4,1,,,,,,,,,,,,,,,,
,3933957933.27729,140.639373779297,89999.6171875,,,,,,8.867323,0.005179509,,0.98304,0,0,,,,,,,,,1,,,,,,,,,,,,,,,,,,,,,,,,,1,4,1,,,,,,,,,,,,,,,,
,3933957933.27945,140.639373779297,89999.6171875,,,,,,7.812738,0.004802193,,0.98304,0,0,,,,,,,,,1,,,,,,,,,,,,,,,,,,,,,,,,,1,4,1,,,,,,,,,,,,,,,,
,3933957933.28161,140.639373779297,89999.6171875,,,,,,6.757815,0.003601645,,0.98304,0,0,,,,,,,,,1,,,,,,,,,,,,,,,,,,,,,,,,,1,4,1,,,,,,,,,,,,,,,,
,3933957933.28377,140.639373779297,89999.6171875,,,,,,5.703231,0.003361535,,0.98304,0,0,,,,,,,,,1,,,,,,,,,,,,,,,,,,,,,,,,,1,4,1,,,,,,,,,,,,,,,,
,3933957933.28593,140.639373779297,89999.6171875,,,,,,4.648308,0.002881316,,0.98304,0,0,,,,,,,,,1,,,,,,,,,,,,,,,,,,,,,,,,,1,4,1,,,,,,,,,,,,,,,,
,3933957933.28809,140.639373779297,89999.6171875,,,,,,3.593724,0.00198948,,0.98304,0,0,,,,,,,,,1,,,,,,,,,,,,,,,,,,,,,,,,,1,4,1,,,,,,,,,,,,,,,,
,3933957933.29025,140.639373779297,89999.6171875,,,,,,2.53914,0.000720329,,0.98304,0,0,,,,,,,,,1,,,,,,,,,,,,,,,,,,,,,,,,,1,4,1,,,,,,,,,,,,,,,,
,3933957933.29241,140.639373779297,89999.6171875,,,,,,1.484217,0.001200548,,0.98304,0,0,,,,,,,,,1,,,,,,,,,,,,,,,,,,,,,,,,,1,4,1,,,,,,,,,,,,,,,,
,3933957933.29457,140.639373779297,89999.6171875,,,,,,0.4296328,0,,0.98304,0,0,,,,,,,,,1,,,,,,,,,,,,,,,,,,,,,,,,,1,4,1,,,,,,,,,,,,,,,,
,3933957933.29673,140.639373779297,89999.6171875,,,,,,-0.6249512,-0.0008575345,,0.98304,0,0,,,,,,,,,1,,,,,,,,,,,,,,,,,,,,,,,,,1,4,1,,,,,,,,,,,,,,,,
,3933957933.29889,140.639373779297,89999.6171875,,,,,,-1.679535,-0.001303453,,0.98304,0,0,,,,,,,,,1,,,,,,,,,,,,,,,,,,,,,,,,,1,4,1,,,,,,,,,,,,,,,,
,3933957933.30105,140.639373779297,89999.6171875,,,,,,-2.734458,-0.001097644,,0.98304,0,0,,,,,,,,,1,,,,,,,,,,,,,,,,,,,,,,,,,1,4,1,,,,,,,,,,,,,,,,
,3933957933.30321,140.639373779297,89999.6171875,,,,,,-3.789042,-0.001955179,,0.98304,0,0,,,,,,,,,1,,,,,,,,,,,,,,,,,,,,,,,,,1,4,1,,,,,,,,,,,,,,,,
,3933957933.30537,140.639373779297,89999.6171875,,,,,,-4.843626,-0.002949919,,0.98304,0,0,,,,,,,,,1,,,,,,,,,,,,,,,,,,,,,,,,,1,4,1,,,,,,,,,,,,,,,,
,3933957933.30753,140.639373779297,89999.6171875,,,,,,-5.89855,-0.004184769,,0.98304,0,0,,,,,,,,,1,,,,,,,,,,,,,,,,,,,,,,,,,1,4,1,,,,,,,,,,,,,,,,
,3933957933.30969,140.639373779297,89999.6171875,,,,,,-6.953134,-0.004013262,,0.98304,0,0,,,,,,,,,1,,,,,,,,,,,,,,,,,,,,,,,,,1,4,1,,,,,,,,,,,,,,,,
,3933957933.31185,140.639373779297,89999.6171875,,,,,,-8.008057,-0.005488221,,0.98304,0,0,,,,,,,,,1,,,,,,,,,,,,,,,,,,,,,,,,,1,4,1,,,,,,,,,,,,,,,,
,3933957933.31401,140.639373779297,89999.6171875,,,,,,-9.062641,-0.005694029,,0.98304,0,0,,,,,,,,,1,,,,,,,,,,,,,,,,,,,,,,,,,1,4,1,,,,,,,,,,,,,,,,
,3933957933.31617,140.639373779297,89999.6171875,,,,,,-9.882911,-0.005762632,,0.98304,0,0,,,,,,,,,1,,,,,,,,,,,,,,,,,,,,,,,,,1,4,1,,,,,,,,,,,,,,,,
,3933957933.31833,140.639373779297,89999.6171875,,,,,,-8.828326,-0.006037043,,0.98304,0,0,,,,,,,,,1,,,,,,,,,,,,,,,,,,,,,,,,,1,4,1,,,,,,,,,,,,,,,,
,3933957933.32049,140.639373779297,89999.6171875,,,,,,-7.773404,-0.005282413,,0.98304,0,0,,,,,,,,,1,,,,,,,,,,,,,,,,,,,,,,,,,1,4,1,,,,,,,,,,,,,,,,
,3933957933.32265,140.639373779297,89999.6171875,,,,,,-6.71882,-0.004527783,,0.98304,0,0,,,,,,,,,1,,,,,,,,,,,,,,,,,,,,,,,,,1,4,1,,,,,,,,,,,,,,,,
,3933957933.32481,140.639373779297,89999.6171875,,,,,,-5.664236,-0.00397896,,0.98304,0,0,,,,,,,,,1,,,,,,,,,,,,,,,,,,,,,,,,,1,4,1,,,,,,,,,,,,,,,,
,3933957933.32697,140.639373779297,89999.6171875,,,,,,-4.609312,-0.003704549,,0.98304,0,0,,,,,,,,,1,,,,,,,,,,,,,,,,,,,,,,,,,1,4,1,,,,,,,,,,,,,,,,
,3933957933.32913,140.639373779297,89999.6171875,,,,,,-3.554728,-0.00322433,,0.98304,0,0,,,,,,,,,1,,,,,,,,,,,,,,,,,,,,,,,,,1,4,1,,,,,,,,,,,,,,,,
,3933957933.33129,140.639373779297,89999.6171875,,,,,,-2.499805,-0.002366795,,0.98304,0,0,,,,,,,,,1,,,,,,,,,,,,,,,,,,,,,,,,,1,4,1,,,,,,,,,,,,,,,,
,3933957933.33345,140.639373779297,89999.6171875,,,,,,-1.445221,-0.001509261,,0.98304,0,0,,,,,,,,,1,,,,,,,,,,,,,,,,,,,,,,,,,1,4,1,,,,,,,,,,,,,,,,
,3933957933.33561,140.639373779297,89999.6171875,,,,,,-0.3906369,-0.001131946,,0.98304,0,0,,,,,,,,,1,,,,,,,,,,,,,,,,,,,,,,,,,1,4,1,,,,,,,,,,,,,,,,
,3933959332.72083,85.1623764038086,89999.8828125,,,,,,0.702943,-0.0003087124,,0.98304,0,0,,,,,,,,,1,,,,,,,,,,,,,,,,,,,,,,,,,1,4,1,,,,,,,,,,,,,,,,
,3933959332.72299,85.1623764038086,89999.8828125,,,,,,1.757866,0.001474959,,0.98304,0,0,,,,,,,,,1,,,,,,,,,,,,,,,,,,,,,,,,,1,4,1,,,,,,,,,,,,,,,,
,3933959332.72515,85.1623764038086,89999.8828125,,,,,,2.81245,0.001680768,,0.98304,0,0,,,,,,,,,1,,,,,,,,,,,,,,,,,,,,,,,,,1,4,1,,,,,,,,,,,,,,,,
,3933959332.72731,85.1623764038086,89999.8828125,,,,,,3.867034,0.002160987,,0.98304,0,0,,,,,,,,,1,,,,,,,,,,,,,,,,,,,,,,,,,1,4,1,,,,,,,,,,,,,,,,
,3933959332.72947,85.1623764038086,89999.8828125,,,,,,4.921957,0.002160987,,0.98304,0,0,,,,,,,,,1,,,,,,,,,,,,,,,,,,,,,,,,,1,4,1,,,,,,,,,,,,,,,,
,3933959332.73163,85.1623764038086,89999.8828125,,,,,,5.976542,0.002126686,,0.98304,0,0,,,,,,,,,1,,,,,,,,,,,,,,,,,,,,,,,,,1,4,1,,,,,,,,,,,,,,,,
,3933959332.73379,85.1623764038086,89999.8828125,,,,,,7.031465,0.00346444,,0.98304,0,0,,,,,,,,,1,,,,,,,,,,,,,,,,,,,,,,,,,1,4,1,,,,,,,,,,,,,,,,
,3933959332.73595,85.1623764038086,89999.8828125,,,,,,8.086049,0.005042303,,0.98304,0,0,,,,,,,,,1,,,,,,,,,,,,,,,,,,,,,,,,,1,4,1,,,,,,,,,,,,,,,,
,3933959332.73811,85.1623764038086,89999.8828125,,,,,,9.140633,0.003841755,,0.98304,0,0,,,,,,,,,1,,,,,,,,,,,,,,,,,,,,,,,,,1,4,1,,,,,,,,,,,,,,,,
,3933959332.74027,85.1623764038086,89999.8828125,,,,,,9.804919,0.005385317,,0.98304,0,0,,,,,,,,,1,,,,,,,,,,,,,,,,,,,,,,,,,1,4,1,,,,,,,,,,,,,,,,
,3933959332.74243,85.1623764038086,89999.8828125,,,,,,8.749996,0.003944659,,0.98304,0,0,,,,,,,,,1,,,,,,,,,,,,,,,,,,,,,,,,,1,4,1,,,,,,,,,,,,,,,,
,3933959332.74459,85.1623764038086,89999.8828125,,,,,,7.695412,0.00397896,,0.98304,0,0,,,,,,,,,1,,,,,,,,,,,,,,,,,,,,,,,,,1,4,1,,,,,,,,,,,,,,,,
,3933959332.74675,85.1623764038086,89999.8828125,,,,,,6.640828,0.002778412,,0.98304,0,0,,,,,,,,,1,,,,,,,,,,,,,,,,,,,,,,,,,1,4,1,,,,,,,,,,,,,,,,
,3933959332.74891,85.1623764038086,89999.8828125,,,,,,5.585905,0.002332494,,0.98304,0,0,,,,,,,,,1,,,,,,,,,,,,,,,,,,,,,,,,,1,4,1,,,,,,,,,,,,,,,,
,3933959332.75107,85.1623764038086,89999.8828125,,,,,,4.531321,0.001577864,,0.98304,0,0,,,,,,,,,1,,,,,,,,,,,,,,,,,,,,,,,,,1,4,1,,,,,,,,,,,,,,,,
,3933959332.75323,85.1623764038086,89999.8828125,,,,,,3.476397,0.0009261373,,0.98304,0,0,,,,,,,,,1,,,,,,,,,,,,,,,,,,,,,,,,,1,4,1,,,,,,,,,,,,,,,,
,3933959332.75539,85.1623764038086,89999.8828125,,,,,,2.421813,0.0001715069,,0.98304,0,0,,,,,,,,,1,,,,,,,,,,,,,,,,,,,,,,,,,1,4,1,,,,,,,,,,,,,,,,
,3933959332.75755,85.1623764038086,89999.8828125,,,,,,1.367229,0.0008575345,,0.98304,0,0,,,,,,,,,1,,,,,,,,,,,,,,,,,,,,,,,,,1,4,1,,,,,,,,,,,,,,,,
,3933959332.75971,85.1623764038086,89999.8828125,,,,,,0.3123061,-0.0005145207,,0.98304,0,0,,,,,,,,,1,,,,,,,,,,,,,,,,,,,,,,,,,1,4,1,,,,,,,,,,,,,,,,
,3933959332.76187,85.1623764038086,89999.8828125,,,,,,-0.7419389,-0.001166247,,0.98304,0,0,,,,,,,,,1,,,,,,,,,,,,,,,,,,,,,,,,,1,4,1,,,,,,,,,,,,,,,,
,3933959332.76403,85.1623764038086,89999.8828125,,,,,,-1.796862,-0.00123485,,0.98304,0,0,,,,,,,,,1,,,,,,,,,,,,,,,,,,,,,,,,,1,4,1,,,,,,,,,,,,,,,,
,3933959332.76619,85.1623764038086,89999.8828125,,,,,,-2.851446,-0.001406357,,0.98304,0,0,,,,,,,,,1,,,,,,,,,,,,,,,,,,,,,,,,,1,4,1,,,,,,,,,,,,,,,,
,3933959332.76835,85.1623764038086,89999.8828125,,,,,,-3.906369,-0.002744111,,0.98304,0,0,,,,,,,,,1,,,,,,,,,,,,,,,,,,,,,,,,,1,4,1,,,,,,,,,,,,,,,,
,3933959332.77051,85.1623764038086,89999.8828125,,,,,,-4.960953,-0.002160987,,0.98304,0,0,,,,,,,,,1,,,,,,,,,,,,,,,,,,,,,,,,,1,4,1,,,,,,,,,,,,,,,,
,3933959332.77267,85.1623764038086,89999.8828125,,,,,,-6.015537,-0.002778412,,0.98304,0,0,,,,,,,,,1,,,,,,,,,,,,,,,,,,,,,,,,,1,4,1,,,,,,,,,,,,,,,,
,3933959332.77483,85.1623764038086,89999.8828125,,,,,,-7.07046,-0.004562084,,0.98304,0,0,,,,,,,,,1,,,,,,,,,,,,,,,,,,,,,,,,,1,4,1,,,,,,,,,,,,,,,,
,3933959332.77699,85.1623764038086,89999.8828125,,,,,,-8.125045,-0.004939399,,0.98304,0,0,,,,,,,,,1,,,,,,,,,,,,,,,,,,,,,,,,,1,4,1,,,,,,,,,,,,,,,,
,3933959332.77915,85.1623764038086,89999.8828125,,,,,,-9.179968,-0.003361535,,0.98304,0,0,,,,,,,,,1,,,,,,,,,,,,,,,,,,,,,,,,,1,4,1,,,,,,,,,,,,,,,,
,3933959332.78131,85.1623764038086,89999.8828125,,,,,,-9.765924,-0.005591125,,0.98304,0,0,,,,,,,,,1,,,,,,,,,,,,,,,,,,,,,,,,,1,4,1,,,,,,,,,,,,,,,,
,3933959332.78347,85.1623764038086,89999.8828125,,,,,,-8.710999,-0.004699289,,0.98304,0,0,,,,,,,,,1,,,,,,,,,,,,,,,,,,,,,,,,,1,4,1,,,,,,,,,,,,,,,,
,3933959332.78563,85.1623764038086,89999.8828125,,,,,,-7.656416,-0.004116166,,0.98304,0,0,,,,,,,,,1,,,,,,,,,,,,,,,,,,,,,,,,,1,4,1,,,,,,,,,,,,,,,,
,3933959332.78779,85.1623764038086,89999.8828125,,,,,,-6.601493,-0.003533042,,0.98304,0,0,,,,,,,,,1,,,,,,,,,,,,,,,,,,,,,,,,,1,4,1,,,,,,,,,,,,,,,,
,3933959332.78995,85.1623764038086,89999.8828125,,,,,,-5.546909,-0.003910358,,0.98304,0,0,,,,,,,,,1,,,,,,,,,,,,,,,,,,,,,,,,,1,4,1,,,,,,,,,,,,,,,,
,3933959332.79211,85.1623764038086,89999.8828125,,,,,,-4.492325,-0.002435398,,0.98304,0,0,,,,,,,,,1,,,,,,,,,,,,,,,,,,,,,,,,,1,4,1,,,,,,,,,,,,,,,,
,3933959332.79427,85.1623764038086,89999.8828125,,,,,,-3.437402,-0.001406357,,0.98304,0,0,,,,,,,,,1,,,,,,,,,,,,,,,,,,,,,,,,,1,4,1,,,,,,,,,,,,,,,,
,3933959332.79643,85.1623764038086,89999.8828125,,,,,,-2.382818,-0.001131946,,0.98304,0,0,,,,,,,,,1,,,,,,,,,,,,,,,,,,,,,,,,,1,4,1,,,,,,,,,,,,,,,,
,3933959332.79859,85.1623764038086,89999.8828125,,,,,,-1.327894,-0.00123485,,0.98304,0,0,,,,,,,,,1,,,,,,,,,,,,,,,,,,,,,,,,,1,4,1,,,,,,,,,,,,,,,,
,3933959332.80075,85.1623764038086,89999.8828125,,,,,,-0.2733102,-0.0004802193,,0.98304,0,0,,,,,,,,,1,,,,,,,,,,,,,,,,,,,,,,,,,1,4,1,,,,,,,,,,,,,,,,
,3933960359.45692,29.7141628265381,90000.0390625,,,,,,0.8202697,0.001097644,,0.98304,0,0,,,,,,,,,1,,,,,,,,,,,,,,,,,,,,,,,,,1,4,1,,,,,,,,,,,,,,,,
,3933960359.45909,29.7141628265381,90000.0390625,,,,,,1.874854,0.000720329,,0.98304,0,0,,,,,,,,,1,,,,,,,,,,,,,,,,,,,,,,,,,1,4,1,,,,,,,,,,,,,,,,
,3933960359.46125,29.7141628265381,90000.0390625,,,,,,2.929777,0.0003430138,,0.98304,0,0,,,,,,,,,1,,,,,,,,,,,,,,,,,,,,,,,,,1,4,1,,,,,,,,,,,,,,,,
,3933960359.46341,29.7141628265381,90000.0390625,,,,,,3.984361,0.001543562,,0.98304,0,0,,,,,,,,,1,,,,,,,,,,,,,,,,,,,,,,,,,1,4,1,,,,,,,,,,,,,,,,
,3933960359.46557,29.7141628265381,90000.0390625,,,,,,5.038945,0.00198948,,0.98304,0,0,,,,,,,,,1,,,,,,,,,,,,,,,,,,,,,,,,,1,4,1,,,,,,,,,,,,,,,,
,3933960359.46773,29.7141628265381,90000.0390625,,,,,,6.093868,0.002435398,,0.98304,0,0,,,,,,,,,1,,,,,,,,,,,,,,,,,,,,,,,,,1,4,1,,,,,,,,,,,,,,,,
,3933960359.46988,29.7141628265381,90000.0390625,,,,,,7.148452,0.002915618,,0.98304,0,0,,,,,,,,,1,,,,,,,,,,,,,,,,,,,,,,,,,1,4,1,,,,,,,,,,,,,,,,
,3933960359.47204,29.7141628265381,90000.0390625,,,,,,8.203376,0.003738851,,0.98304,0,0,,,,,,,,,1,,,,,,,,,,,,,,,,,,,,,,,,,1,4,1,,,,,,,,,,,,,,,,
,3933960359.47421,29.7141628265381,90000.0390625,,,,,,9.257959,0.004493481,,0.98304,0,0,,,,,,,,,1,,,,,,,,,,,,,,,,,,,,,,,,,1,4,1,,,,,,,,,,,,,,,,
,3933960359.47637,29.7141628265381,90000.0390625,,,,,,9.687593,0.00346444,,0.98304,0,0,,,,,,,,,1,,,,,,,,,,,,,,,,,,,,,,,,,1,4,1,,,,,,,,,,,,,,,,
,3933960359.47853,29.7141628265381,90000.0390625,,,,,,8.633008,0.004767892,,0.98304,0,0,,,,,,,,,1,,,,,,,,,,,,,,,,,,,,,,,,,1,4,1,,,,,,,,,,,,,,,,
,3933960359.48069,29.7141628265381,90000.0390625,,,,,,7.578085,0.003190028,,0.98304,0,0,,,,,,,,,1,,,,,,,,,,,,,,,,,,,,,,,,,1,4,1,,,,,,,,,,,,,,,,
,3933960359.48285,29.7141628265381,90000.0390625,,,,,,6.523501,0.003533042,,0.98304,0,0,,,,,,,,,1,,,,,,,,,,,,,,,,,,,,,,,,,1,4,1,,,,,,,,,,,,,,,,
,3933960359.485,29.7141628265381,90000.0390625,,,,,,5.468917,0.002126686,,0.98304,0,0,,,,,,,,,1,,,,,,,,,,,,,,,,,,,,,,,,,1,4,1,,,,,,,,,,,,,,,,
,3933960359.48717,29.7141628265381,90000.0390625,,,,,,4.413994,0.002298193,,0.98304,0,0,,,,,,,,,1,,,,,,,,,,,,,,,,,,,,,,,,,1,4,1,,,,,,,,,,,,,,,,
,3933960359.48933,29.7141628265381,90000.0390625,,,,,,3.35941,0.0005145207,,0.98304,0,0,,,,,,,,,1,,,,,,,,,,,,,,,,,,,,,,,,,1,4,1,,,,,,,,,,,,,,,,
,3933960359.49149,29.7141628265381,90000.0390625,,,,,,2.304487,0.0005145207,,0.98304,0,0,,,,,,,,,1,,,,,,,,,,,,,,,,,,,,,,,,,1,4,1,,,,,,,,,,,,,,,,
,3933960359.49365,29.7141628265381,90000.0390625,,,,,,1.249902,0.0007546304,,0.98304,0,0,,,,,,,,,1,,,,,,,,,,,,,,,,,,,,,,,,,1,4,1,,,,,,,,,,,,,,,,
,3933960359.49581,29.7141628265381,90000.0390625,,,,,,0.1953185,0.0001372055,,0.98304,0,0,,,,,,,,,1,,,,,,,,,,,,,,,,,,,,,,,,,1,4,1,,,,,,,,,,,,,,,,
,3933960359.49796,29.7141628265381,90000.0390625,,,,,,-0.8592656,-0.001680768,,0.98304,0,0,,,,,,,,,1,,,,,,,,,,,,,,,,,,,,,,,,,1,4,1,,,,,,,,,,,,,,,,
,3933960359.50012,29.7141628265381,90000.0390625,,,,,,-1.91385,-0.0006174249,,0.98304,0,0,,,,,,,,,1,,,,,,,,,,,,,,,,,,,,,,,,,1,4,1,,,,,,,,,,,,,,,,
,3933960359.50229,29.7141628265381,90000.0390625,,,,,,-2.968773,-0.001509261,,0.98304,0,0,,,,,,,,,1,,,,,,,,,,,,,,,,,,,,,,,,,1,4,1,,,,,,,,,,,,,,,,
,3933960359.50445,29.7141628265381,90000.0390625,,,,,,-4.023357,-0.002641206,,0.98304,0,0,,,,,,,,,1,,,,,,,,,,,,,,,,,,,,,,,,,1,4,1,,,,,,,,,,,,,,,,
,3933960359.50661,29.7141628265381,90000.0390625,,,,,,-5.07828,-0.002401097,,0.98304,0,0,,,,,,,,,1,,,,,,,,,,,,,,,,,,,,,,,,,1,4,1,,,,,,,,,,,,,,,,
,3933960359.50877,29.7141628265381,90000.0390625,,,,,,-6.132864,-0.00322433,,0.98304,0,0,,,,,,,,,1,,,,,,,,,,,,,,,,,,,,,,,,,1,4,1,,,,,,,,,,,,,,,,
,3933960359.51093,29.7141628265381,90000.0390625,,,,,,-7.187448,-0.004013262,,0.98304,0,0,,,,,,,,,1,,,,,,,,,,,,,,,,,,,,,,,,,1,4,1,,,,,,,,,,,,,,,,
,3933960359.51308,29.7141628265381,90000.0390625,,,,,,-8.242372,-0.004047563,,0.98304,0,0,,,,,,,,,1,,,,,,,,,,,,,,,,,,,,,,,,,1,4,1,,,,,,,,,,,,,,,,
,3933960359.51525,29.7141628265381,90000.0390625,,,,,,-9.296955,-0.004905098,,0.98304,0,0,,,,,,,,,1,,,,,,,,,,,,,,,,,,,,,,,,,1,4,1,,,,,,,,,,,,,,,,
,3933960359.51741,29.7141628265381,90000.0390625,,,,,,-9.648597,-0.004184769,,0.98304,0,0,,,,,,,,,1,,,,,,,,,,,,,,,,,,,,,,,,,1,4,1,,,,,,,,,,,,,,,,
,3933960359.51957,29.7141628265381,90000.0390625,,,,,,-8.594012,-0.004116166,,0.98304,0,0,,,,,,,,,1,,,,,,,,,,,,,,,,,,,,,,,,,1,4,1,,,,,,,,,,,,,,,,
,3933960359.52173,29.7141628265381,90000.0390625,,,,,,-7.539089,-0.004047563,,0.98304,0,0,,,,,,,,,1,,,,,,,,,,,,,,,,,,,,,,,,,1,4,1,,,,,,,,,,,,,,,,
,3933960359.52389,29.7141628265381,90000.0390625,,,,,,-6.484505,-0.003841755,,0.98304,0,0,,,,,,,,,1,,,,,,,,,,,,,,,,,,,,,,,,,1,4,1,,,,,,,,,,,,,,,,
,3933960359.52604,29.7141628265381,90000.0390625,,,,,,-5.429582,-0.002401097,,0.98304,0,0,,,,,,,,,1,,,,,,,,,,,,,,,,,,,,,,,,,1,4,1,,,,,,,,,,,,,,,,
,3933960359.5282,29.7141628265381,90000.0390625,,,,,,-4.374998,-0.002504001,,0.98304,0,0,,,,,,,,,1,,,,,,,,,,,,,,,,,,,,,,,,,1,4,1,,,,,,,,,,,,,,,,
,3933960359.53037,29.7141628265381,90000.0390625,,,,,,-3.320414,-0.001440658,,0.98304,0,0,,,,,,,,,1,,,,,,,,,,,,,,,,,,,,,,,,,1,4,1,,,,,,,,,,,,,,,,
,3933960359.53253,29.7141628265381,90000.0390625,,,,,,-2.265491,-0.001372055,,0.98304,0,0,,,,,,,,,1,,,,,,,,,,,,,,,,,,,,,,,,,1,4,1,,,,,,,,,,,,,,,,
,3933960359.53469,29.7141628265381,90000.0390625,,,,,,-1.210907,-0.0006860276,,0.98304,0,0,,,,,,,,,1,,,,,,,,,,,,,,,,,,,,,,,,,1,4,1,,,,,,,,,,,,,,,,
,3933960359.53685,29.7141628265381,90000.0390625,,,,,,-0.1559835,0.0003430138,,0.98304,0,0,,,,,,,,,1,,,,,,,,,,,,,,,,,,,,,,,,,1,4,1,,,,,,,,,,,,,,,,
,3933961798.57418,1.99758362770081,90000.0234375,,,,,,0.9372573,0.0002744111,,0.98304,0,0,,,,,,,,,1,,,,,,,,,,,,,,,,,,,,,,,,,1,4,1,,,,,,,,,,,,,,,,
,3933961798.57634,1.99758362770081,90000.0234375,,,,,,1.99218,0.0003430138,,0.98304,0,0,,,,,,,,,1,,,,,,,,,,,,,,,,,,,,,,,,,1,4,1,,,,,,,,,,,,,,,,
,3933961798.5785,1.99758362770081,90000.0234375,,,,,,3.046765,0.0003773152,,0.98304,0,0,,,,,,,,,1,,,,,,,,,,,,,,,,,,,,,,,,,1,4,1,,,,,,,,,,,,,,,,
,3933961798.58066,1.99758362770081,90000.0234375,,,,,,4.101688,0.0009261373,,0.98304,0,0,,,,,,,,,1,,,,,,,,,,,,,,,,,,,,,,,,,1,4,1,,,,,,,,,,,,,,,,
,3933961798.58282,1.99758362770081,90000.0234375,,,,,,5.156272,0.001509261,,0.98304,0,0,,,,,,,,,1,,,,,,,,,,,,,,,,,,,,,,,,,1,4,1,,,,,,,,,,,,,,,,
,3933961798.58498,1.99758362770081,90000.0234375,,,,,,6.210856,0.001817973,,0.98304,0,0,,,,,,,,,1,,,,,,,,,,,,,,,,,,,,,,,,,1,4,1,,,,,,,,,,,,,,,,
,3933961798.58714,1.99758362770081,90000.0234375,,,,,,7.265779,0.002881316,,0.98304,0,0,,,,,,,,,1,,,,,,,,,,,,,,,,,,,,,,,,,1,4,1,,,,,,,,,,,,,,,,
,3933961798.5893,1.99758362770081,90000.0234375,,,,,,8.320363,0.002709809,,0.98304,0,0,,,,,,,,,1,,,,,,,,,,,,,,,,,,,,,,,,,1,4,1,,,,,,,,,,,,,,,,
,3933961798.59146,1.99758362770081,90000.0234375,,,,,,9.375286,0.003773152,,0.98304,0,0,,,,,,,,,1,,,,,,,,,,,,,,,,,,,,,,,,,1,4,1,,,,,,,,,,,,,,,,
,3933961798.59362,1.99758362770081,90000.0234375,,,,,,9.570604,0.004013262,,0.98304,0,0,,,,,,,,,1,,,,,,,,,,,,,,,,,,,,,,,,,1,4,1,,,,,,,,,,,,,,,,
,3933961798.59578,1.99758362770081,90000.0234375,,,,,,8.515681,0.003601645,,0.98304,0,0,,,,,,,,,1,,,,,,,,,,,,,,,,,,,,,,,,,1,4,1,,,,,,,,,,,,,,,,
,3933961798.59794,1.99758362770081,90000.0234375,,,,,,7.461097,0.002126686,,0.98304,0,0,,,,,,,,,1,,,,,,,,,,,,,,,,,,,,,,,,,1,4,1,,,,,,,,,,,,,,,,
,3933961798.6001,1.99758362770081,90000.0234375,,,,,,6.406174,0.001783672,,0.98304,0,0,,,,,,,,,1,,,,,,,,,,,,,,,,,,,,,,,,,1,4,1,,,,,,,,,,,,,,,,
,3933961798.60226,1.99758362770081,90000.0234375,,,,,,5.35159,0.001474959,,0.98304,0,0,,,,,,,,,1,,,,,,,,,,,,,,,,,,,,,,,,,1,4,1,,,,,,,,,,,,,,,,
,3933961798.60442,1.99758362770081,90000.0234375,,,,,,4.297006,0.001131946,,0.98304,0,0,,,,,,,,,1,,,,,,,,,,,,,,,,,,,,,,,,,1,4,1,,,,,,,,,,,,,,,,
,3933961798.60658,1.99758362770081,90000.0234375,,,,,,3.242083,0.001783672,,0.98304,0,0,,,,,,,,,1,,,,,,,,,,,,,,,,,,,,,,,,,1,4,1,,,,,,,,,,,,,,,,
,3933961798.60874,1.99758362770081,90000.0234375,,,,,,2.187499,0.0005488221,,0.98304,0,0,,,,,,,,,1,,,,,,,,,,,,,,,,,,,,,,,,,1,4,1,,,,,,,,,,,,,,,,
,3933961798.6109,1.99758362770081,90000.0234375,,,,,,1.132576,0.0003773152,,0.98304,0,0,,,,,,,,,1,,,,,,,,,,,,,,,,,,,,,,,,,1,4,1,,,,,,,,,,,,,,,,
,3933961798.61306,1.99758362770081,90000.0234375,,,,,,0.07799175,0.0005488221,,0.98304,0,0,,,,,,,,,1,,,,,,,,,,,,,,,,,,,,,,,,,1,4,1,,,,,,,,,,,,,,,,
,3933961798.61522,1.99758362770081,90000.0234375,,,,,,-0.9765923,-0.0002058083,,0.98304,0,0,,,,,,,,,1,,,,,,,,,,,,,,,,,,,,,,,,,1,4,1,,,,,,,,,,,,,,,,
,3933961798.61738,1.99758362770081,90000.0234375,,,,,,-2.031176,-0.001646466,,0.98304,0,0,,,,,,,,,1,,,,,,,,,,,,,,,,,,,,,,,,,1,4,1,,,,,,,,,,,,,,,,
,3933961798.61954,1.99758362770081,90000.0234375,,,,,,-3.08576,-0.001886576,,0.98304,0,0,,,,,,,,,1,,,,,,,,,,,,,,,,,,,,,,,,,1,4,1,,,,,,,,,,,,,,,,
,3933961798.6217,1.99758362770081,90000.0234375,,,,,,-4.140684,-0.002435398,,0.98304,0,0,,,,,,,,,1,,,,,,,,,,,,,,,,,,,,,,,,,1,4,1,,,,,,,,,,,,,,,,
,3933961798.62386,1.99758362770081,90000.0234375,,,,,,-5.195268,-0.002606905,,0.98304,0,0,,,,,,,,,1,,,,,,,,,,,,,,,,,,,,,,,,,1,4,1,,,,,,,,,,,,,,,,
,3933961798.62602,1.99758362770081,90000.0234375,,,,,,-6.250191,-0.003121426,,0.98304,0,0,,,,,,,,,1,,,,,,,,,,,,,,,,,,,,,,,,,1,4,1,,,,,,,,,,,,,,,,
,3933961798.62818,1.99758362770081,90000.0234375,,,,,,-7.304775,-0.003121426,,0.98304,0,0,,,,,,,,,1,,,,,,,,,,,,,,,,,,,,,,,,,1,4,1,,,,,,,,,,,,,,,,
,3933961798.63034,1.99758362770081,90000.0234375,,,,,,-8.359359,-0.00397896,,0.98304,0,0,,,,,,,,,1,,,,,,,,,,,,,,,,,,,,,,,,,1,4,1,,,,,,,,,,,,,,,,
,3933961798.6325,1.99758362770081,90000.0234375,,,,,,-9.414282,-0.003635946,,0.98304,0,0,,,,,,,,,1,,,,,,,,,,,,,,,,,,,,,,,,,1,4,1,,,,,,,,,,,,,,,,
,3933961798.63466,1.99758362770081,90000.0234375,,,,,,-9.53127,-0.005591125,,0.98304,0,0,,,,,,,,,1,,,,,,,,,,,,,,,,,,,,,,,,,1,4,1,,,,,,,,,,,,,,,,
,3933961798.63682,1.99758362770081,90000.0234375,,,,,,-8.476686,-0.003292933,,0.98304,0,0,,,,,,,,,1,,,,,,,,,,,,,,,,,,,,,,,,,1,4,1,,,,,,,,,,,,,,,,
,3933961798.63898,1.99758362770081,90000.0234375,,,,,,-7.422101,-0.00322433,,0.98304,0,0,,,,,,,,,1,,,,,,,,,,,,,,,,,,,,,,,,,1,4,1,,,,,,,,,,,,,,,,
,3933961798.64114,1.99758362770081,90000.0234375,,,,,,-6.367178,-0.003533042,,0.98304,0,0,,,,,,,,,1,,,,,,,,,,,,,,,,,,,,,,,,,1,4,1,,,,,,,,,,,,,,,,
,3933961798.6433,1.99758362770081,90000.0234375,,,,,,-5.312594,-0.002915618,,0.98304,0,0,,,,,,,,,1,,,,,,,,,,,,,,,,,,,,,,,,,1,4,1,,,,,,,,,,,,,,,,
,3933961798.64546,1.99758362770081,90000.0234375,,,,,,-4.257671,-0.0006860276,,0.98304,0,0,,,,,,,,,1,,,,,,,,,,,,,,,,,,,,,,,,,1,4,1,,,,,,,,,,,,,,,,
,3933961798.64762,1.99758362770081,90000.0234375,,,,,,-3.203087,-0.0006517263,,0.98304,0,0,,,,,,,,,1,,,,,,,,,,,,,,,,,,,,,,,,,1,4,1,,,,,,,,,,,,,,,,
,3933961798.64978,1.99758362770081,90000.0234375,,,,,,-2.148503,-0.000891836,,0.98304,0,0,,,,,,,,,1,,,,,,,,,,,,,,,,,,,,,,,,,1,4,1,,,,,,,,,,,,,,,,
,3933961798.65194,1.99758362770081,90000.0234375,,,,,,-1.09358,-0.0006860276,,0.98304,0,0,,,,,,,,,1,,,,,,,,,,,,,,,,,,,,,,,,,1,4,1,,,,,,,,,,,,,,,,
,3933961798.65402,1.99758362770081,90000.0234375,,,,,,-0.07799175,0.0002058083,,0.98304,0,0,,,,,,,,,1,,,,,,,,,,,,,,,,,,,,,,,,,1,4,1,,,,,,,,,,,,,,,,