File: data/IV_semiconductor.dat
[Header]
;Copyright 2015, Quantum Design, Inc. All rights reserved.
FILEOPENTIME, 0.0, ,4/25/2024 9:25:51 AM
BYAPP, Electrical Transport Option, Release 1.2.0 Build 0
INFO, APPNAME, ETOption, Release 1.2.0 Build 0
TITLE, Electrical Transport Option (CAN)
STARTUPAXIS, X, 2, LINEAR, AUTO
STARTUPAXIS, Y1, 7, LINEAR, AUTO
STARTUPAXIS, Y2, 9, LINEAR, AUTO
STARTUPAXIS, Y3, 27, LINEAR, AUTO
STARTUPAXIS, Y4, 29, LINEAR, AUTO
TIMEMODE, SECONDS, RELATIVE
PLOT_APPEARANCE, ALL, HORZ_GRID_ON, VERT_GRID_ON,,AUTO_LINES
RECORDS, ALL_RECORDS
DATATYPE, COMMENT, 1
[Data]
Comment,Time Stamp (s),Temperature (K),Field (Oe),Sample Position (deg),Chamber Pressure (Torr),Resistance Ch1 (Ohms),Resistance Std. Dev. Ch1 (Ohms),Phase Angle Ch1 (deg),I-V Current Ch1 (mA),I-V Voltage Ch1 (V),Frequency Ch1 (Hz),Averaging Time Ch1 (s),AC Current Ch1 (mA),DC Current Ch1 (mA),Voltage Ampl Ch1 (V),In Phase Voltage Ampl Ch1 (V),Quadrature Voltage Ch1 (V),AC Voltage Ch1 (V),DC Voltage Ch1 (V),Current Ampl Ch1 (mA),In Phase Current Ch1 (mA),Quadrature Current Ch1 (mA),Gain Ch1,2nd Harmonic Ch1 (dB),3rd Harmonic Ch1 (dB),Resistance Ch2 (Ohms),Resistance Std. Dev. Ch2 (Ohms),Phase Angle Ch2 (deg),I-V Current Ch2 (mA),I-V Voltage Ch2 (V),Frequency Ch2 (Hz),Averaging Time Ch2 (s),AC Current Ch2 (mA),DC Current Ch2 (mA),Voltage Ampl Ch2 (V),In Phase Voltage Ampl Ch2 (V),Quadrature Voltage Ch2 (V),AC Voltage Ch2 (V),DC Voltage Ch2 (V),Current Ampl Ch2 (mA),In Phase Current Ch2 (mA),Quadrature Current Ch2 (mA),Gain Ch2,2nd Harmonic Ch2 (dB),3rd Harmonic Ch2 (dB),ETO Status Code,ETO Measurement Mode,Temperature Status (code),Field Status (code),Chamber Status (code),ETO Channel 1,ETO Channel 2,ETO Channel 3,ETO Channel 4,ETO Channel 5,ETO Channel 6,ETO Channel 7,ETO Channel 8,ETO Channel 9,ETO Channel 10,ETO Channel 11,ETO Channel 12,ETO Channel 13,ETO Channel 14,ETO Channel 15,ETO Channel 16

,3923198730.83664,300.059478759766,9999.76953125,,,,,,0,-0.0007546304,,5.24288,0.0001,0,,,,,,,,,1,,,,,,,,,,,,,,,,,,,,,,,33557376,0,1,4,3,,,,,,,,,,,,,,,,
,3923198730.93264,300.059478759766,9999.76953125,,,,,,1.171911E-05,-0.0001372055,,5.24288,0.0001,0,,,,,,,,,1,,,,,,,,,,,,,,,,,,,,,,,33557376,0,1,4,3,,,,,,,,,,,,,,,,
,3923198731.02864,300.059478759766,9999.76953125,,,,,,2.343822E-05,0.001337754,,5.24288,0.0001,0,,,,,,,,,1,,,,,,,,,,,,,,,,,,,,,,,33557376,0,1,4,3,,,,,,,,,,,,,,,,
,3923198731.12464,300.059478759766,9999.76953125,,,,,,3.515732E-05,0.001577864,,5.24288,0.0001,0,,,,,,,,,1,,,,,,,,,,,,,,,,,,,,,,,33557376,0,1,4,3,,,,,,,,,,,,,,,,
,3923198731.22064,300.059478759766,9999.76953125,,,,,,4.687643E-05,0.003327234,,5.24288,0.0001,0,,,,,,,,,1,,,,,,,,,,,,,,,,,,,,,,,33557376,0,1,4,3,,,,,,,,,,,,,,,,
,3923198731.31664,300.059478759766,9999.76953125,,,,,,5.859553E-05,0.00346444,,5.24288,0.0001,0,,,,,,,,,1,,,,,,,,,,,,,,,,,,,,,,,33557376,0,1,4,3,,,,,,,,,,,,,,,,
,3923198731.41264,300.059478759766,9999.76953125,,,,,,7.031464E-05,0.004527783,,5.24288,0.0001,0,,,,,,,,,1,,,,,,,,,,,,,,,,,,,,,,,33557376,0,1,4,3,,,,,,,,,,,,,,,,
,3923198731.50864,300.059478759766,9999.76953125,,,,,,8.203375E-05,0.0049737,,5.24288,0.0001,0,,,,,,,,,1,,,,,,,,,,,,,,,,,,,,,,,33557376,0,1,4,3,,,,,,,,,,,,,,,,
,3923198731.60464,300.059478759766,9999.76953125,,,,,,9.375286E-05,0.006174249,,5.24288,0.0001,0,,,,,,,,,1,,,,,,,,,,,,,,,,,,,,,,,33557376,0,1,4,3,,,,,,,,,,,,,,,,
,3923198731.70064,300.059478759766,9999.76953125,,,,,,9.453278E-05,0.005899838,,5.24288,0.0001,0,,,,,,,,,1,,,,,,,,,,,,,,,,,,,,,,,33557376,0,1,4,3,,,,,,,,,,,,,,,,
,3923198731.79664,300.059478759766,9999.76953125,,,,,,8.281367E-05,0.005625427,,5.24288,0.0001,0,,,,,,,,,1,,,,,,,,,,,,,,,,,,,,,,,33557376,0,1,4,3,,,,,,,,,,,,,,,,
,3923198731.89264,300.059478759766,9999.76953125,,,,,,7.109456E-05,0.004939399,,5.24288,0.0001,0,,,,,,,,,1,,,,,,,,,,,,,,,,,,,,,,,33557376,0,1,4,3,,,,,,,,,,,,,,,,
,3923198731.98864,300.059478759766,9999.76953125,,,,,,5.937546E-05,0.00346444,,5.24288,0.0001,0,,,,,,,,,1,,,,,,,,,,,,,,,,,,,,,,,33557376,0,1,4,3,,,,,,,,,,,,,,,,
,3923198732.08464,300.059478759766,9999.76953125,,,,,,4.765635E-05,0.002778412,,5.24288,0.0001,0,,,,,,,,,1,,,,,,,,,,,,,,,,,,,,,,,33557376,0,1,4,3,,,,,,,,,,,,,,,,
,3923198732.18064,300.059478759766,9999.76953125,,,,,,3.593724E-05,0.003121426,,5.24288,0.0001,0,,,,,,,,,1,,,,,,,,,,,,,,,,,,,,,,,33557376,0,1,4,3,,,,,,,,,,,,,,,,
,3923198732.27664,300.059478759766,9999.76953125,,,,,,2.421813E-05,0.002366795,,5.24288,0.0001,0,,,,,,,,,1,,,,,,,,,,,,,,,,,,,,,,,33557376,0,1,4,3,,,,,,,,,,,,,,,,
,3923198732.37264,300.059478759766,9999.76953125,,,,,,1.249902E-05,0.0009261373,,5.24288,0.0001,0,,,,,,,,,1,,,,,,,,,,,,,,,,,,,,,,,33557376,0,1,4,3,,,,,,,,,,,,,,,,
,3923198732.46864,300.059478759766,9999.76953125,,,,,,7.799175E-07,-0.0001715069,,5.24288,0.0001,0,,,,,,,,,1,,,,,,,,,,,,,,,,,,,,,,,33557376,0,1,4,3,,,,,,,,,,,,,,,,
,3923198732.56464,300.059478759766,9999.76953125,,,,,,-1.09358E-05,-0.001474959,,5.24288,0.0001,0,,,,,,,,,1,,,,,,,,,,,,,,,,,,,,,,,33557376,0,1,4,3,,,,,,,,,,,,,,,,
,3923198732.66064,300.059478759766,9999.76953125,,,,,,-2.265491E-05,-0.001577864,,5.24288,0.0001,0,,,,,,,,,1,,,,,,,,,,,,,,,,,,,,,,,33557376,0,1,4,3,,,,,,,,,,,,,,,,
,3923198732.75664,300.059478759766,9999.76953125,,,,,,-3.437401E-05,-0.00298422,,5.24288,0.0001,0,,,,,,,,,1,,,,,,,,,,,,,,,,,,,,,,,33557376,0,1,4,3,,,,,,,,,,,,,,,,
,3923198732.85264,300.059478759766,9999.76953125,,,,,,-4.609312E-05,-0.004081864,,5.24288,0.0001,0,,,,,,,,,1,,,,,,,,,,,,,,,,,,,,,,,33557376,0,1,4,3,,,,,,,,,,,,,,,,
,3923198732.94864,300.059478759766,9999.76953125,,,,,,-5.781223E-05,-0.004047563,,5.24288,0.0001,0,,,,,,,,,1,,,,,,,,,,,,,,,,,,,,,,,33557376,0,1,4,3,,,,,,,,,,,,,,,,
,3923198733.04464,300.059478759766,9999.76953125,,,,,,-6.953134E-05,-0.005522523,,5.24288,0.0001,0,,,,,,,,,1,,,,,,,,,,,,,,,,,,,,,,,33557376,0,1,4,3,,,,,,,,,,,,,,,,
,3923198733.14064,300.059478759766,9999.76953125,,,,,,-8.125044E-05,-0.005316714,,5.24288,0.0001,0,,,,,,,,,1,,,,,,,,,,,,,,,,,,,,,,,33557376,0,1,4,3,,,,,,,,,,,,,,,,
,3923198733.23664,300.059478759766,9999.76953125,,,,,,-9.296955E-05,-0.00696318,,5.24288,0.0001,0,,,,,,,,,1,,,,,,,,,,,,,,,,,,,,,,,33557376,0,1,4,3,,,,,,,,,,,,,,,,
,3923198733.33264,300.059478759766,9999.76953125,,,,,,-9.531269E-05,-0.007168989,,5.24288,0.0001,0,,,,,,,,,1,,,,,,,,,,,,,,,,,,,,,,,33557376,0,1,4,3,,,,,,,,,,,,,,,,
,3923198733.42864,300.059478759766,9999.76953125,,,,,,-8.359359E-05,-0.00644866,,5.24288,0.0001,0,,,,,,,,,1,,,,,,,,,,,,,,,,,,,,,,,33557376,0,1,4,3,,,,,,,,,,,,,,,,
,3923198733.52464,300.059478759766,9999.76953125,,,,,,-7.187448E-05,-0.005796934,,5.24288,0.0001,0,,,,,,,,,1,,,,,,,,,,,,,,,,,,,,,,,33557376,0,1,4,3,,,,,,,,,,,,,,,,
,3923198733.62064,300.059478759766,9999.76953125,,,,,,-6.015537E-05,-0.004802193,,5.24288,0.0001,0,,,,,,,,,1,,,,,,,,,,,,,,,,,,,,,,,33557376,0,1,4,3,,,,,,,,,,,,,,,,
,3923198733.71664,300.059478759766,9999.76953125,,,,,,-4.843626E-05,-0.003395837,,5.24288,0.0001,0,,,,,,,,,1,,,,,,,,,,,,,,,,,,,,,,,33557376,0,1,4,3,,,,,,,,,,,,,,,,
,3923198733.81264,300.059478759766,9999.76953125,,,,,,-3.671716E-05,-0.002263891,,5.24288,0.0001,0,,,,,,,,,1,,,,,,,,,,,,,,,,,,,,,,,33557376,0,1,4,3,,,,,,,,,,,,,,,,
,3923198733.90864,300.059478759766,9999.76953125,,,,,,-2.499805E-05,-0.002058083,,5.24288,0.0001,0,,,,,,,,,1,,,,,,,,,,,,,,,,,,,,,,,33557376,0,1,4,3,,,,,,,,,,,,,,,,
,3923198734.00464,300.059478759766,9999.76953125,,,,,,-1.327894E-05,-0.0003773152,,5.24288,0.0001,0,,,,,,,,,1,,,,,,,,,,,,,,,,,,,,,,,33557376,0,1,4,3,,,,,,,,,,,,,,,,
,3923198734.10064,300.059478759766,9999.76953125,,,,,,-1.559835E-06,-0.0005145207,,5.24288,0.0001,0,,,,,,,,,1,,,,,,,,,,,,,,,,,,,,,,,33557376,0,1,4,3,,,,,,,,,,,,,,,,
,3923198806.03445,300.033081054688,19999.818359375,,,,,,1.054584E-05,0.000720329,,5.24288,0.0001,0,,,,,,,,,1,,,,,,,,,,,,,,,,,,,,,,,33557376,0,1,4,3,,,,,,,,,,,,,,,,
,3923198806.13045,300.033081054688,19999.818359375,,,,,,2.226495E-05,0.002092384,,5.24288,0.0001,0,,,,,,,,,1,,,,,,,,,,,,,,,,,,,,,,,33557376,0,1,4,3,,,,,,,,,,,,,,,,
,3923198806.22645,300.033081054688,19999.818359375,,,,,,3.398406E-05,0.002092384,,5.24288,0.0001,0,,,,,,,,,1,,,,,,,,,,,,,,,,,,,,,,,33557376,0,1,4,3,,,,,,,,,,,,,,,,
,3923198806.32245,300.033081054688,19999.818359375,,,,,,4.570316E-05,0.002195288,,5.24288,0.0001,0,,,,,,,,,1,,,,,,,,,,,,,,,,,,,,,,,33557376,0,1,4,3,,,,,,,,,,,,,,,,
,3923198806.41845,300.033081054688,19999.818359375,,,,,,5.742227E-05,0.003670248,,5.24288,0.0001,0,,,,,,,,,1,,,,,,,,,,,,,,,,,,,,,,,33557376,0,1,4,3,,,,,,,,,,,,,,,,
,3923198806.51445,300.033081054688,19999.818359375,,,,,,6.914137E-05,0.004493481,,5.24288,0.0001,0,,,,,,,,,1,,,,,,,,,,,,,,,,,,,,,,,33557376,0,1,4,3,,,,,,,,,,,,,,,,
,3923198806.61045,300.033081054688,19999.818359375,,,,,,8.086048E-05,0.00521381,,5.24288,0.0001,0,,,,,,,,,1,,,,,,,,,,,,,,,,,,,,,,,33557376,0,1,4,3,,,,,,,,,,,,,,,,
,3923198806.70645,300.033081054688,19999.818359375,,,,,,9.257959E-05,0.007271893,,5.24288,0.0001,0,,,,,,,,,1,,,,,,,,,,,,,,,,,,,,,,,33557376,0,1,4,3,,,,,,,,,,,,,,,,
,3923198806.80245,300.033081054688,19999.818359375,,,,,,9.570604E-05,0.005591125,,5.24288,0.0001,0,,,,,,,,,1,,,,,,,,,,,,,,,,,,,,,,,33557376,0,1,4,3,,,,,,,,,,,,,,,,
,3923198806.89845,300.033081054688,19999.818359375,,,,,,8.398694E-05,0.005248111,,5.24288,0.0001,0,,,,,,,,,1,,,,,,,,,,,,,,,,,,,,,,,33557376,0,1,4,3,,,,,,,,,,,,,,,,
,3923198806.99445,300.033081054688,19999.818359375,,,,,,7.226783E-05,0.004356275,,5.24288,0.0001,0,,,,,,,,,1,,,,,,,,,,,,,,,,,,,,,,,33557376,0,1,4,3,,,,,,,,,,,,,,,,
,3923198807.09045,300.033081054688,19999.818359375,,,,,,6.054872E-05,0.003944659,,5.24288,0.0001,0,,,,,,,,,1,,,,,,,,,,,,,,,,,,,,,,,33557376,0,1,4,3,,,,,,,,,,,,,,,,
,3923198807.18645,300.033081054688,19999.818359375,,,,,,4.882961E-05,0.004287673,,5.24288,0.0001,0,,,,,,,,,1,,,,,,,,,,,,,,,,,,,,,,,33557376,0,1,4,3,,,,,,,,,,,,,,,,
,3923198807.28245,300.033081054688,19999.818359375,,,,,,3.711051E-05,0.002298193,,5.24288,0.0001,0,,,,,,,,,1,,,,,,,,,,,,,,,,,,,,,,,33557376,0,1,4,3,,,,,,,,,,,,,,,,
,3923198807.37845,300.033081054688,19999.818359375,,,,,,2.53914E-05,0.0005831235,,5.24288,0.0001,0,,,,,,,,,1,,,,,,,,,,,,,,,,,,,,,,,33557376,0,1,4,3,,,,,,,,,,,,,,,,
,3923198807.47445,300.033081054688,19999.818359375,,,,,,1.367229E-05,0.000445918,,5.24288,0.0001,0,,,,,,,,,1,,,,,,,,,,,,,,,,,,,,,,,33557376,0,1,4,3,,,,,,,,,,,,,,,,
,3923198807.57045,300.033081054688,19999.818359375,,,,,,1.953185E-06,0.001097644,,5.24288,0.0001,0,,,,,,,,,1,,,,,,,,,,,,,,,,,,,,,,,33557376,0,1,4,3,,,,,,,,,,,,,,,,
,3923198807.66645,300.033081054688,19999.818359375,,,,,,-9.765923E-06,-0.001715069,,5.24288,0.0001,0,,,,,,,,,1,,,,,,,,,,,,,,,,,,,,,,,33557376,0,1,4,3,,,,,,,,,,,,,,,,
,3923198807.76245,300.033081054688,19999.818359375,,,,,,-2.148503E-05,-0.002332494,,5.24288,0.0001,0,,,,,,,,,1,,,,,,,,,,,,,,,,,,,,,,,33557376,0,1,4,3,,,,,,,,,,,,,,,,
,3923198807.85845,300.033081054688,19999.818359375,,,,,,-3.320414E-05,-0.003018522,,5.24288,0.0001,0,,,,,,,,,1,,,,,,,,,,,,,,,,,,,,,,,33557376,0,1,4,3,,,,,,,,,,,,,,,,
,3923198807.95445,300.033081054688,19999.818359375,,,,,,-4.492325E-05,-0.002092384,,5.24288,0.0001,0,,,,,,,,,1,,,,,,,,,,,,,,,,,,,,,,,33557376,0,1,4,3,,,,,,,,,,,,,,,,
,3923198808.05045,300.033081054688,19999.818359375,,,,,,-5.664235E-05,-0.004390577,,5.24288,0.0001,0,,,,,,,,,1,,,,,,,,,,,,,,,,,,,,,,,33557376,0,1,4,3,,,,,,,,,,,,,,,,
,3923198808.14645,300.033081054688,19999.818359375,,,,,,-6.836146E-05,-0.0049737,,5.24288,0.0001,0,,,,,,,,,1,,,,,,,,,,,,,,,,,,,,,,,33557376,0,1,4,3,,,,,,,,,,,,,,,,
,3923198808.24245,300.033081054688,19999.818359375,,,,,,-8.008056E-05,-0.005796934,,5.24288,0.0001,0,,,,,,,,,1,,,,,,,,,,,,,,,,,,,,,,,33557376,0,1,4,3,,,,,,,,,,,,,,,,
,3923198808.33845,300.033081054688,19999.818359375,,,,,,-9.179967E-05,-0.007168989,,5.24288,0.0001,0,,,,,,,,,1,,,,,,,,,,,,,,,,,,,,,,,33557376,0,1,4,3,,,,,,,,,,,,,,,,
,3923198808.43445,300.033081054688,19999.818359375,,,,,,-9.648596E-05,-0.006620167,,5.24288,0.0001,0,,,,,,,,,1,,,,,,,,,,,,,,,,,,,,,,,33557376,0,1,4,3,,,,,,,,,,,,,,,,
,3923198808.53045,300.033081054688,19999.818359375,,,,,,-8.476686E-05,-0.005728331,,5.24288,0.0001,0,,,,,,,,,1,,,,,,,,,,,,,,,,,,,,,,,33557376,0,1,4,3,,,,,,,,,,,,,,,,
,3923198808.62645,300.033081054688,19999.818359375,,,,,,-7.304775E-05,-0.005899838,,5.24288,0.0001,0,,,,,,,,,1,,,,,,,,,,,,,,,,,,,,,,,33557376,0,1,4,3,,,,,,,,,,,,,,,,
,3923198808.72245,300.033081054688,19999.818359375,,,,,,-6.132864E-05,-0.005145207,,5.24288,0.0001,0,,,,,,,,,1,,,,,,,,,,,,,,,,,,,,,,,33557376,0,1,4,3,,,,,,,,,,,,,,,,
,3923198808.81845,300.033081054688,19999.818359375,,,,,,-4.960953E-05,-0.003533042,,5.24288,0.0001,0,,,,,,,,,1,,,,,,,,,,,,,,,,,,,,,,,33557376,0,1,4,3,,,,,,,,,,,,,,,,
,3923198808.91445,300.033081054688,19999.818359375,,,,,,-3.789042E-05,-0.00346444,,5.24288,0.0001,0,,,,,,,,,1,,,,,,,,,,,,,,,,,,,,,,,33557376,0,1,4,3,,,,,,,,,,,,,,,,
,3923198809.01045,300.033081054688,19999.818359375,,,,,,-2.617132E-05,-0.002092384,,5.24288,0.0001,0,,,,,,,,,1,,,,,,,,,,,,,,,,,,,,,,,33557376,0,1,4,3,,,,,,,,,,,,,,,,
,3923198809.10645,300.033081054688,19999.818359375,,,,,,-1.445221E-05,-0.001372055,,5.24288,0.0001,0,,,,,,,,,1,,,,,,,,,,,,,,,,,,,,,,,33557376,0,1,4,3,,,,,,,,,,,,,,,,
,3923198809.20245,300.033081054688,19999.818359375,,,,,,-2.733102E-06,-0.0005488221,,5.24288,0.0001,0,,,,,,,,,1,,,,,,,,,,,,,,,,,,,,,,,33557376,0,1,4,3,,,,,,,,,,,,,,,,
,3923198879.99013,300.019500732422,29999.6953125,,,,,,9.372573E-06,0.0002401097,,5.24288,0.0001,0,,,,,,,,,1,,,,,,,,,,,,,,,,,,,,,,,33557376,0,1,4,3,,,,,,,,,,,,,,,,
,3923198880.08613,300.019500732422,29999.6953125,,,,,,2.109168E-05,0.001063343,,5.24288,0.0001,0,,,,,,,,,1,,,,,,,,,,,,,,,,,,,,,,,33557376,0,1,4,3,,,,,,,,,,,,,,,,
,3923198880.18213,300.019500732422,29999.6953125,,,,,,3.281079E-05,0.001577864,,5.24288,0.0001,0,,,,,,,,,1,,,,,,,,,,,,,,,,,,,,,,,33557376,0,1,4,3,,,,,,,,,,,,,,,,
,3923198880.27813,300.019500732422,29999.6953125,,,,,,4.452989E-05,0.004664988,,5.24288,0.0001,0,,,,,,,,,1,,,,,,,,,,,,,,,,,,,,,,,33557376,0,1,4,3,,,,,,,,,,,,,,,,
,3923198880.37413,300.019500732422,29999.6953125,,,,,,5.6249E-05,0.003498741,,5.24288,0.0001,0,,,,,,,,,1,,,,,,,,,,,,,,,,,,,,,,,33557376,0,1,4,3,,,,,,,,,,,,,,,,
,3923198880.47013,300.019500732422,29999.6953125,,,,,,6.796811E-05,0.003773152,,5.24288,0.0001,0,,,,,,,,,1,,,,,,,,,,,,,,,,,,,,,,,33557376,0,1,4,3,,,,,,,,,,,,,,,,
,3923198880.56613,300.019500732422,29999.6953125,,,,,,7.968722E-05,0.005145207,,5.24288,0.0001,0,,,,,,,,,1,,,,,,,,,,,,,,,,,,,,,,,33557376,0,1,4,3,,,,,,,,,,,,,,,,
,3923198880.66213,300.019500732422,29999.6953125,,,,,,9.140633E-05,0.005591125,,5.24288,0.0001,0,,,,,,,,,1,,,,,,,,,,,,,,,,,,,,,,,33557376,0,1,4,3,,,,,,,,,,,,,,,,
,3923198880.75813,300.019500732422,29999.6953125,,,,,,9.687592E-05,0.006311454,,5.24288,0.0001,0,,,,,,,,,1,,,,,,,,,,,,,,,,,,,,,,,33557376,0,1,4,3,,,,,,,,,,,,,,,,
,3923198880.85413,300.019500732422,29999.6953125,,,,,,8.515681E-05,0.005762632,,5.24288,0.0001,0,,,,,,,,,1,,,,,,,,,,,,,,,,,,,,,,,33557376,0,1,4,3,,,,,,,,,,,,,,,,
,3923198880.95013,300.019500732422,29999.6953125,,,,,,7.34377E-05,0.004939399,,5.24288,0.0001,0,,,,,,,,,1,,,,,,,,,,,,,,,,,,,,,,,33557376,0,1,4,3,,,,,,,,,,,,,,,,
,3923198881.04613,300.019500732422,29999.6953125,,,,,,6.171859E-05,0.003773152,,5.24288,0.0001,0,,,,,,,,,1,,,,,,,,,,,,,,,,,,,,,,,33557376,0,1,4,3,,,,,,,,,,,,,,,,
,3923198881.14213,300.019500732422,29999.6953125,,,,,,4.999949E-05,0.003704549,,5.24288,0.0001,0,,,,,,,,,1,,,,,,,,,,,,,,,,,,,,,,,33557376,0,1,4,3,,,,,,,,,,,,,,,,
,3923198881.23813,300.019500732422,29999.6953125,,,,,,3.828038E-05,0.002092384,,5.24288,0.0001,0,,,,,,,,,1,,,,,,,,,,,,,,,,,,,,,,,33557376,0,1,4,3,,,,,,,,,,,,,,,,
,3923198881.33413,300.019500732422,29999.6953125,,,,,,2.656128E-05,0.001269151,,5.24288,0.0001,0,,,,,,,,,1,,,,,,,,,,,,,,,,,,,,,,,33557376,0,1,4,3,,,,,,,,,,,,,,,,
,3923198881.43013,300.019500732422,29999.6953125,,,,,,1.484217E-05,0.0009604387,,5.24288,0.0001,0,,,,,,,,,1,,,,,,,,,,,,,,,,,,,,,,,33557376,0,1,4,3,,,,,,,,,,,,,,,,
,3923198881.52613,300.019500732422,29999.6953125,,,,,,3.123061E-06,0.0008575345,,5.24288,0.0001,0,,,,,,,,,1,,,,,,,,,,,,,,,,,,,,,,,33557376,0,1,4,3,,,,,,,,,,,,,,,,
,3923198881.62213,300.019500732422,29999.6953125,,,,,,-8.592656E-06,-0.0009604387,,5.24288,0.0001,0,,,,,,,,,1,,,,,,,,,,,,,,,,,,,,,,,33557376,0,1,4,3,,,,,,,,,,,,,,,,
,3923198881.71813,300.019500732422,29999.6953125,,,,,,-2.031176E-05,-0.002812713,,5.24288,0.0001,0,,,,,,,,,1,,,,,,,,,,,,,,,,,,,,,,,33557376,0,1,4,3,,,,,,,,,,,,,,,,
,3923198881.81413,300.019500732422,29999.6953125,,,,,,-3.203087E-05,-0.003018522,,5.24288,0.0001,0,,,,,,,,,1,,,,,,,,,,,,,,,,,,,,,,,33557376,0,1,4,3,,,,,,,,,,,,,,,,
,3923198881.91013,300.019500732422,29999.6953125,,,,,,-4.374998E-05,-0.002332494,,5.24288,0.0001,0,,,,,,,,,1,,,,,,,,,,,,,,,,,,,,,,,33557376,0,1,4,3,,,,,,,,,,,,,,,,
,3923198882.00613,300.019500732422,29999.6953125,,,,,,-5.546909E-05,-0.004047563,,5.24288,0.0001,0,,,,,,,,,1,,,,,,,,,,,,,,,,,,,,,,,33557376,0,1,4,3,,,,,,,,,,,,,,,,
,3923198882.10213,300.019500732422,29999.6953125,,,,,,-6.718819E-05,-0.0049737,,5.24288,0.0001,0,,,,,,,,,1,,,,,,,,,,,,,,,,,,,,,,,33557376,0,1,4,3,,,,,,,,,,,,,,,,
,3923198882.19813,300.019500732422,29999.6953125,,,,,,-7.89073E-05,-0.00620855,,5.24288,0.0001,0,,,,,,,,,1,,,,,,,,,,,,,,,,,,,,,,,33557376,0,1,4,3,,,,,,,,,,,,,,,,
,3923198882.29413,300.019500732422,29999.6953125,,,,,,-9.062641E-05,-0.006551564,,5.24288,0.0001,0,,,,,,,,,1,,,,,,,,,,,,,,,,,,,,,,,33557376,0,1,4,3,,,,,,,,,,,,,,,,
,3923198882.39013,300.019500732422,29999.6953125,,,,,,-9.765923E-05,-0.007614907,,5.24288,0.0001,0,,,,,,,,,1,,,,,,,,,,,,,,,,,,,,,,,33557376,0,1,4,3,,,,,,,,,,,,,,,,
,3923198882.48613,300.019500732422,29999.6953125,,,,,,-8.594012E-05,-0.006928879,,5.24288,0.0001,0,,,,,,,,,1,,,,,,,,,,,,,,,,,,,,,,,33557376,0,1,4,3,,,,,,,,,,,,,,,,
,3923198882.58213,300.019500732422,29999.6953125,,,,,,-7.422101E-05,-0.005865536,,5.24288,0.0001,0,,,,,,,,,1,,,,,,,,,,,,,,,,,,,,,,,33557376,0,1,4,3,,,,,,,,,,,,,,,,
,3923198882.67813,300.019500732422,29999.6953125,,,,,,-6.250191E-05,-0.004493481,,5.24288,0.0001,0,,,,,,,,,1,,,,,,,,,,,,,,,,,,,,,,,33557376,0,1,4,3,,,,,,,,,,,,,,,,
,3923198882.77413,300.019500732422,29999.6953125,,,,,,-5.07828E-05,-0.003704549,,5.24288,0.0001,0,,,,,,,,,1,,,,,,,,,,,,,,,,,,,,,,,33557376,0,1,4,3,,,,,,,,,,,,,,,,
,3923198882.87013,300.019500732422,29999.6953125,,,,,,-3.906369E-05,-0.002949919,,5.24288,0.0001,0,,,,,,,,,1,,,,,,,,,,,,,,,,,,,,,,,33557376,0,1,4,3,,,,,,,,,,,,,,,,
,3923198882.96613,300.019500732422,29999.6953125,,,,,,-2.734458E-05,-0.00198948,,5.24288,0.0001,0,,,,,,,,,1,,,,,,,,,,,,,,,,,,,,,,,33557376,0,1,4,3,,,,,,,,,,,,,,,,
,3923198883.06213,300.019500732422,29999.6953125,,,,,,-1.562548E-05,-0.001029041,,5.24288,0.0001,0,,,,,,,,,1,,,,,,,,,,,,,,,,,,,,,,,33557376,0,1,4,3,,,,,,,,,,,,,,,,
,3923198883.15813,300.019500732422,29999.6953125,,,,,,-3.906369E-06,0.0006860276,,5.24288,0.0001,0,,,,,,,,,1,,,,,,,,,,,,,,,,,,,,,,,33557376,0,1,4,3,,,,,,,,,,,,,,,,
,3923198954.45874,300.010620117188,39999.7890625,,,,,,8.202697E-06,0,,5.24288,0.0001,0,,,,,,,,,1,,,,,,,,,,,,,,,,,,,,,,,33557376,0,1,4,3,,,,,,,,,,,,,,,,
,3923198954.55474,300.010620117188,39999.7890625,,,,,,1.99218E-05,0.001680768,,5.24288,0.0001,0,,,,,,,,,1,,,,,,,,,,,,,,,,,,,,,,,33557376,0,1,4,3,,,,,,,,,,,,,,,,
,3923198954.65074,300.010620117188,39999.7890625,,,,,,3.164091E-05,0.003361535,,5.24288,0.0001,0,,,,,,,,,1,,,,,,,,,,,,,,,,,,,,,,,33557376,0,1,4,3,,,,,,,,,,,,,,,,
,3923198954.74674,300.010620117188,39999.7890625,,,,,,4.336002E-05,0.00322433,,5.24288,0.0001,0,,,,,,,,,1,,,,,,,,,,,,,,,,,,,,,,,33557376,0,1,4,3,,,,,,,,,,,,,,,,
,3923198954.84274,300.010620117188,39999.7890625,,,,,,5.507913E-05,0.002881316,,5.24288,0.0001,0,,,,,,,,,1,,,,,,,,,,,,,,,,,,,,,,,33557376,0,1,4,3,,,,,,,,,,,,,,,,
,3923198954.93874,300.010620117188,39999.7890625,,,,,,6.679823E-05,0.004287673,,5.24288,0.0001,0,,,,,,,,,1,,,,,,,,,,,,,,,,,,,,,,,33557376,0,1,4,3,,,,,,,,,,,,,,,,
,3923198955.03474,300.010620117188,39999.7890625,,,,,,7.851734E-05,0.005179509,,5.24288,0.0001,0,,,,,,,,,1,,,,,,,,,,,,,,,,,,,,,,,33557376,0,1,4,3,,,,,,,,,,,,,,,,
,3923198955.13074,300.010620117188,39999.7890625,,,,,,9.023645E-05,0.00644866,,5.24288,0.0001,0,,,,,,,,,1,,,,,,,,,,,,,,,,,,,,,,,33557376,0,1,4,3,,,,,,,,,,,,,,,,
,3923198955.22674,300.010620117188,39999.7890625,,,,,,9.804919E-05,0.006139948,,5.24288,0.0001,0,,,,,,,,,1,,,,,,,,,,,,,,,,,,,,,,,33557376,0,1,4,3,,,,,,,,,,,,,,,,
,3923198955.32274,300.010620117188,39999.7890625,,,,,,8.633008E-05,0.005694029,,5.24288,0.0001,0,,,,,,,,,1,,,,,,,,,,,,,,,,,,,,,,,33557376,0,1,4,3,,,,,,,,,,,,,,,,
,3923198955.41874,300.010620117188,39999.7890625,,,,,,7.461097E-05,0.004390577,,5.24288,0.0001,0,,,,,,,,,1,,,,,,,,,,,,,,,,,,,,,,,33557376,0,1,4,3,,,,,,,,,,,,,,,,
,3923198955.51474,300.010620117188,39999.7890625,,,,,,6.289186E-05,0.00397896,,5.24288,0.0001,0,,,,,,,,,1,,,,,,,,,,,,,,,,,,,,,,,33557376,0,1,4,3,,,,,,,,,,,,,,,,
,3923198955.61074,300.010620117188,39999.7890625,,,,,,5.117276E-05,0.003327234,,5.24288,0.0001,0,,,,,,,,,1,,,,,,,,,,,,,,,,,,,,,,,33557376,0,1,4,3,,,,,,,,,,,,,,,,
,3923198955.70674,300.010620117188,39999.7890625,,,,,,3.945365E-05,0.003258631,,5.24288,0.0001,0,,,,,,,,,1,,,,,,,,,,,,,,,,,,,,,,,33557376,0,1,4,3,,,,,,,,,,,,,,,,
,3923198955.80274,300.010620117188,39999.7890625,,,,,,2.773454E-05,0.00174937,,5.24288,0.0001,0,,,,,,,,,1,,,,,,,,,,,,,,,,,,,,,,,33557376,0,1,4,3,,,,,,,,,,,,,,,,
,3923198955.89874,300.010620117188,39999.7890625,,,,,,1.601544E-05,0.0004802193,,5.24288,0.0001,0,,,,,,,,,1,,,,,,,,,,,,,,,,,,,,,,,33557376,0,1,4,3,,,,,,,,,,,,,,,,
,3923198955.99474,300.010620117188,39999.7890625,,,,,,4.296328E-06,-0.000445918,,5.24288,0.0001,0,,,,,,,,,1,,,,,,,,,,,,,,,,,,,,,,,33557376,0,1,4,3,,,,,,,,,,,,,,,,
,3923198956.09074,300.010620117188,39999.7890625,,,,,,-7.419389E-06,-0.001097644,,5.24288,0.0001,0,,,,,,,,,1,,,,,,,,,,,,,,,,,,,,,,,33557376,0,1,4,3,,,,,,,,,,,,,,,,
,3923198956.18674,300.010620117188,39999.7890625,,,,,,-1.91385E-05,-0.002023781,,5.24288,0.0001,0,,,,,,,,,1,,,,,,,,,,,,,,,,,,,,,,,33557376,0,1,4,3,,,,,,,,,,,,,,,,
,3923198956.28274,300.010620117188,39999.7890625,,,,,,-3.08576E-05,-0.002949919,,5.24288,0.0001,0,,,,,,,,,1,,,,,,,,,,,,,,,,,,,,,,,33557376,0,1,4,3,,,,,,,,,,,,,,,,
,3923198956.37874,300.010620117188,39999.7890625,,,,,,-4.257671E-05,-0.003670248,,5.24288,0.0001,0,,,,,,,,,1,,,,,,,,,,,,,,,,,,,,,,,33557376,0,1,4,3,,,,,,,,,,,,,,,,
,3923198956.47474,300.010620117188,39999.7890625,,,,,,-5.429582E-05,-0.002572604,,5.24288,0.0001,0,,,,,,,,,1,,,,,,,,,,,,,,,,,,,,,,,33557376,0,1,4,3,,,,,,,,,,,,,,,,
,3923198956.57074,300.010620117188,39999.7890625,,,,,,-6.601492E-05,-0.005008002,,5.24288,0.0001,0,,,,,,,,,1,,,,,,,,,,,,,,,,,,,,,,,33557376,0,1,4,3,,,,,,,,,,,,,,,,
,3923198956.66674,300.010620117188,39999.7890625,,,,,,-7.773403E-05,-0.005728331,,5.24288,0.0001,0,,,,,,,,,1,,,,,,,,,,,,,,,,,,,,,,,33557376,0,1,4,3,,,,,,,,,,,,,,,,
,3923198956.76274,300.010620117188,39999.7890625,,,,,,-8.945314E-05,-0.005556824,,5.24288,0.0001,0,,,,,,,,,1,,,,,,,,,,,,,,,,,,,,,,,33557376,0,1,4,3,,,,,,,,,,,,,,,,
,3923198956.85874,300.010620117188,39999.7890625,,,,,,-9.882911E-05,-0.0074434,,5.24288,0.0001,0,,,,,,,,,1,,,,,,,,,,,,,,,,,,,,,,,33557376,0,1,4,3,,,,,,,,,,,,,,,,
,3923198956.95474,300.010620117188,39999.7890625,,,,,,-8.711E-05,-0.006517263,,5.24288,0.0001,0,,,,,,,,,1,,,,,,,,,,,,,,,,,,,,,,,33557376,0,1,4,3,,,,,,,,,,,,,,,,
,3923198957.05074,300.010620117188,39999.7890625,,,,,,-7.539089E-05,-0.005934139,,5.24288,0.0001,0,,,,,,,,,1,,,,,,,,,,,,,,,,,,,,,,,33557376,0,1,4,3,,,,,,,,,,,,,,,,
,3923198957.14674,300.010620117188,39999.7890625,,,,,,-6.367178E-05,-0.004527783,,5.24288,0.0001,0,,,,,,,,,1,,,,,,,,,,,,,,,,,,,,,,,33557376,0,1,4,3,,,,,,,,,,,,,,,,
,3923198957.24274,300.010620117188,39999.7890625,,,,,,-5.195267E-05,-0.00322433,,5.24288,0.0001,0,,,,,,,,,1,,,,,,,,,,,,,,,,,,,,,,,33557376,0,1,4,3,,,,,,,,,,,,,,,,
,3923198957.33874,300.010620117188,39999.7890625,,,,,,-4.023357E-05,-0.002401097,,5.24288,0.0001,0,,,,,,,,,1,,,,,,,,,,,,,,,,,,,,,,,33557376,0,1,4,3,,,,,,,,,,,,,,,,
,3923198957.43474,300.010620117188,39999.7890625,,,,,,-2.851446E-05,-0.002847015,,5.24288,0.0001,0,,,,,,,,,1,,,,,,,,,,,,,,,,,,,,,,,33557376,0,1,4,3,,,,,,,,,,,,,,,,
,3923198957.53074,300.010620117188,39999.7890625,,,,,,-1.679535E-05,-0.001852275,,5.24288,0.0001,0,,,,,,,,,1,,,,,,,,,,,,,,,,,,,,,,,33557376,0,1,4,3,,,,,,,,,,,,,,,,
,3923198957.62674,300.010620117188,39999.7890625,,,,,,-5.076245E-06,-0.001063343,,5.24288,0.0001,0,,,,,,,,,1,,,,,,,,,,,,,,,,,,,,,,,33557376,0,1,4,3,,,,,,,,,,,,,,,,
,3923199028.98394,300.01171875,49999.80078125,,,,,,7.02943E-06,0.0002401097,,5.24288,0.0001,0,,,,,,,,,1,,,,,,,,,,,,,,,,,,,,,,,33557376,0,1,4,3,,,,,,,,,,,,,,,,
,3923199029.07994,300.01171875,49999.80078125,,,,,,1.874854E-05,6.860276E-05,,5.24288,0.0001,0,,,,,,,,,1,,,,,,,,,,,,,,,,,,,,,,,33557376,0,1,4,3,,,,,,,,,,,,,,,,
,3923199029.17594,300.01171875,49999.80078125,,,,,,3.046765E-05,0.001543562,,5.24288,0.0001,0,,,,,,,,,1,,,,,,,,,,,,,,,,,,,,,,,33557376,0,1,4,3,,,,,,,,,,,,,,,,
,3923199029.27194,300.01171875,49999.80078125,,,,,,4.218675E-05,0.003052823,,5.24288,0.0001,0,,,,,,,,,1,,,,,,,,,,,,,,,,,,,,,,,33557376,0,1,4,3,,,,,,,,,,,,,,,,
,3923199029.36794,300.01171875,49999.80078125,,,,,,5.390586E-05,0.003773152,,5.24288,0.0001,0,,,,,,,,,1,,,,,,,,,,,,,,,,,,,,,,,33557376,0,1,4,3,,,,,,,,,,,,,,,,
,3923199029.46394,300.01171875,49999.80078125,,,,,,6.562497E-05,0.003773152,,5.24288,0.0001,0,,,,,,,,,1,,,,,,,,,,,,,,,,,,,,,,,33557376,0,1,4,3,,,,,,,,,,,,,,,,
,3923199029.55994,300.01171875,49999.80078125,,,,,,7.734408E-05,0.004459179,,5.24288,0.0001,0,,,,,,,,,1,,,,,,,,,,,,,,,,,,,,,,,33557376,0,1,4,3,,,,,,,,,,,,,,,,
,3923199029.65594,300.01171875,49999.80078125,,,,,,8.906318E-05,0.006414359,,5.24288,0.0001,0,,,,,,,,,1,,,,,,,,,,,,,,,,,,,,,,,33557376,0,1,4,3,,,,,,,,,,,,,,,,
,3923199029.75194,300.01171875,49999.80078125,,,,,,9.921906E-05,0.00644866,,5.24288,0.0001,0,,,,,,,,,1,,,,,,,,,,,,,,,,,,,,,,,33557376,0,1,4,3,,,,,,,,,,,,,,,,
,3923199029.84794,300.01171875,49999.80078125,,,,,,8.749995E-05,0.00521381,,5.24288,0.0001,0,,,,,,,,,1,,,,,,,,,,,,,,,,,,,,,,,33557376,0,1,4,3,,,,,,,,,,,,,,,,
,3923199029.94394,300.01171875,49999.80078125,,,,,,7.578084E-05,0.004390577,,5.24288,0.0001,0,,,,,,,,,1,,,,,,,,,,,,,,,,,,,,,,,33557376,0,1,4,3,,,,,,,,,,,,,,,,
,3923199030.03994,300.01171875,49999.80078125,,,,,,6.406174E-05,0.003190028,,5.24288,0.0001,0,,,,,,,,,1,,,,,,,,,,,,,,,,,,,,,,,33557376,0,1,4,3,,,,,,,,,,,,,,,,
,3923199030.13594,300.01171875,49999.80078125,,,,,,5.234264E-05,0.003361535,,5.24288,0.0001,0,,,,,,,,,1,,,,,,,,,,,,,,,,,,,,,,,33557376,0,1,4,3,,,,,,,,,,,,,,,,
,3923199030.23194,300.01171875,49999.80078125,,,,,,4.062353E-05,0.002058083,,5.24288,0.0001,0,,,,,,,,,1,,,,,,,,,,,,,,,,,,,,,,,33557376,0,1,4,3,,,,,,,,,,,,,,,,
,3923199030.32794,300.01171875,49999.80078125,,,,,,2.890442E-05,0.001131946,,5.24288,0.0001,0,,,,,,,,,1,,,,,,,,,,,,,,,,,,,,,,,33557376,0,1,4,3,,,,,,,,,,,,,,,,
,3923199030.42394,300.01171875,49999.80078125,,,,,,1.718531E-05,0.0001372055,,5.24288,0.0001,0,,,,,,,,,1,,,,,,,,,,,,,,,,,,,,,,,33557376,0,1,4,3,,,,,,,,,,,,,,,,
,3923199030.51994,300.01171875,49999.80078125,,,,,,5.466204E-06,-0.0003087124,,5.24288,0.0001,0,,,,,,,,,1,,,,,,,,,,,,,,,,,,,,,,,33557376,0,1,4,3,,,,,,,,,,,,,,,,
,3923199030.61594,300.01171875,49999.80078125,,,,,,-6.249512E-06,-0.0009261373,,5.24288,0.0001,0,,,,,,,,,1,,,,,,,,,,,,,,,,,,,,,,,33557376,0,1,4,3,,,,,,,,,,,,,,,,
,3923199030.71194,300.01171875,49999.80078125,,,,,,-1.796862E-05,-0.001543562,,5.24288,0.0001,0,,,,,,,,,1,,,,,,,,,,,,,,,,,,,,,,,33557376,0,1,4,3,,,,,,,,,,,,,,,,
,3923199030.80794,300.01171875,49999.80078125,,,,,,-2.968773E-05,-0.002366795,,5.24288,0.0001,0,,,,,,,,,1,,,,,,,,,,,,,,,,,,,,,,,33557376,0,1,4,3,,,,,,,,,,,,,,,,
,3923199030.90394,300.01171875,49999.80078125,,,,,,-4.140683E-05,-0.003292933,,5.24288,0.0001,0,,,,,,,,,1,,,,,,,,,,,,,,,,,,,,,,,33557376,0,1,4,3,,,,,,,,,,,,,,,,
,3923199030.99994,300.01171875,49999.80078125,,,,,,-5.312594E-05,-0.002435398,,5.24288,0.0001,0,,,,,,,,,1,,,,,,,,,,,,,,,,,,,,,,,33557376,0,1,4,3,,,,,,,,,,,,,,,,
,3923199031.09594,300.01171875,49999.80078125,,,,,,-6.484505E-05,-0.005556824,,5.24288,0.0001,0,,,,,,,,,1,,,,,,,,,,,,,,,,,,,,,,,33557376,0,1,4,3,,,,,,,,,,,,,,,,
,3923199031.19194,300.01171875,49999.80078125,,,,,,-7.656416E-05,-0.00545392,,5.24288,0.0001,0,,,,,,,,,1,,,,,,,,,,,,,,,,,,,,,,,33557376,0,1,4,3,,,,,,,,,,,,,,,,
,3923199031.28794,300.01171875,49999.80078125,,,,,,-8.828326E-05,-0.00644866,,5.24288,0.0001,0,,,,,,,,,1,,,,,,,,,,,,,,,,,,,,,,,33557376,0,1,4,3,,,,,,,,,,,,,,,,
,3923199031.38394,300.01171875,49999.80078125,,,,,,-0.0001000024,-0.00720329,,5.24288,0.0001,0,,,,,,,,,1,,,,,,,,,,,,,,,,,,,,,,,33557376,0,1,4,3,,,,,,,,,,,,,,,,
,3923199031.47994,300.01171875,49999.80078125,,,,,,-8.828326E-05,-0.006345755,,5.24288,0.0001,0,,,,,,,,,1,,,,,,,,,,,,,,,,,,,,,,,33557376,0,1,4,3,,,,,,,,,,,,,,,,
,3923199031.57594,300.01171875,49999.80078125,,,,,,-7.656416E-05,-0.005694029,,5.24288,0.0001,0,,,,,,,,,1,,,,,,,,,,,,,,,,,,,,,,,33557376,0,1,4,3,,,,,,,,,,,,,,,,
,3923199031.67194,300.01171875,49999.80078125,,,,,,-6.484505E-05,-0.004870796,,5.24288,0.0001,0,,,,,,,,,1,,,,,,,,,,,,,,,,,,,,,,,33557376,0,1,4,3,,,,,,,,,,,,,,,,
,3923199031.76794,300.01171875,49999.80078125,,,,,,-5.312594E-05,-0.004802193,,5.24288,0.0001,0,,,,,,,,,1,,,,,,,,,,,,,,,,,,,,,,,33557376,0,1,4,3,,,,,,,,,,,,,,,,
,3923199031.86394,300.01171875,49999.80078125,,,,,,-4.140683E-05,-0.002915618,,5.24288,0.0001,0,,,,,,,,,1,,,,,,,,,,,,,,,,,,,,,,,33557376,0,1,4,3,,,,,,,,,,,,,,,,
,3923199031.95994,300.01171875,49999.80078125,,,,,,-2.968773E-05,-0.00222959,,5.24288,0.0001,0,,,,,,,,,1,,,,,,,,,,,,,,,,,,,,,,,33557376,0,1,4,3,,,,,,,,,,,,,,,,
,3923199032.05594,300.01171875,49999.80078125,,,,,,-1.796862E-05,-0.001509261,,5.24288,0.0001,0,,,,,,,,,1,,,,,,,,,,,,,,,,,,,,,,,33557376,0,1,4,3,,,,,,,,,,,,,,,,
,3923199032.15194,300.01171875,49999.80078125,,,,,,-6.249512E-06,-0.0005831235,,5.24288,0.0001,0,,,,,,,,,1,,,,,,,,,,,,,,,,,,,,,,,33557376,0,1,4,3,,,,,,,,,,,,,,,,
,3923199103.65121,300.004486083984,59999.66796875,,,,,,5.859554E-06,-0.001131946,,5.24288,0.0001,0,,,,,,,,,1,,,,,,,,,,,,,,,,,,,,,,,33557376,0,1,4,3,,,,,,,,,,,,,,,,
,3923199103.74721,300.004486083984,59999.66796875,,,,,,1.757866E-05,0.0002744111,,5.24288,0.0001,0,,,,,,,,,1,,,,,,,,,,,,,,,,,,,,,,,33557376,0,1,4,3,,,,,,,,,,,,,,,,
,3923199103.84321,300.004486083984,59999.66796875,,,,,,2.929777E-05,0.0008575345,,5.24288,0.0001,0,,,,,,,,,1,,,,,,,,,,,,,,,,,,,,,,,33557376,0,1,4,3,,,,,,,,,,,,,,,,
,3923199103.93921,300.004486083984,59999.66796875,,,,,,4.101688E-05,0.002538302,,5.24288,0.0001,0,,,,,,,,,1,,,,,,,,,,,,,,,,,,,,,,,33557376,0,1,4,3,,,,,,,,,,,,,,,,
,3923199104.0352,300.004486083984,59999.66796875,,,,,,5.273598E-05,0.004870796,,5.24288,0.0001,0,,,,,,,,,1,,,,,,,,,,,,,,,,,,,,,,,33557376,0,1,4,3,,,,,,,,,,,,,,,,
,3923199104.13121,300.004486083984,59999.66796875,,,,,,6.445509E-05,0.004081864,,5.24288,0.0001,0,,,,,,,,,1,,,,,,,,,,,,,,,,,,,,,,,33557376,0,1,4,3,,,,,,,,,,,,,,,,
,3923199104.22721,300.004486083984,59999.66796875,,,,,,7.61742E-05,0.005042303,,5.24288,0.0001,0,,,,,,,,,1,,,,,,,,,,,,,,,,,,,,,,,33557376,0,1,4,3,,,,,,,,,,,,,,,,
,3923199104.32321,300.004486083984,59999.66796875,,,,,,8.789331E-05,0.005591125,,5.24288,0.0001,0,,,,,,,,,1,,,,,,,,,,,,,,,,,,,,,,,33557376,0,1,4,3,,,,,,,,,,,,,,,,
,3923199104.41921,300.004486083984,59999.66796875,,,,,,9.961241E-05,0.005522523,,5.24288,0.0001,0,,,,,,,,,1,,,,,,,,,,,,,,,,,,,,,,,33557376,0,1,4,3,,,,,,,,,,,,,,,,
,3923199104.5152,300.004486083984,59999.66796875,,,,,,8.867322E-05,0.005351015,,5.24288,0.0001,0,,,,,,,,,1,,,,,,,,,,,,,,,,,,,,,,,33557376,0,1,4,3,,,,,,,,,,,,,,,,
,3923199104.61121,300.004486083984,59999.66796875,,,,,,7.695411E-05,0.005110906,,5.24288,0.0001,0,,,,,,,,,1,,,,,,,,,,,,,,,,,,,,,,,33557376,0,1,4,3,,,,,,,,,,,,,,,,
,3923199104.7072,300.004486083984,59999.66796875,,,,,,6.523501E-05,0.003601645,,5.24288,0.0001,0,,,,,,,,,1,,,,,,,,,,,,,,,,,,,,,,,33557376,0,1,4,3,,,,,,,,,,,,,,,,
,3923199104.80321,300.004486083984,59999.66796875,,,,,,5.35159E-05,0.003567344,,5.24288,0.0001,0,,,,,,,,,1,,,,,,,,,,,,,,,,,,,,,,,33557376,0,1,4,3,,,,,,,,,,,,,,,,
,3923199104.89921,300.004486083984,59999.66796875,,,,,,4.179679E-05,0.002709809,,5.24288,0.0001,0,,,,,,,,,1,,,,,,,,,,,,,,,,,,,,,,,33557376,0,1,4,3,,,,,,,,,,,,,,,,
,3923199104.9952,300.004486083984,59999.66796875,,,,,,3.007769E-05,0.002949919,,5.24288,0.0001,0,,,,,,,,,1,,,,,,,,,,,,,,,,,,,,,,,33557376,0,1,4,3,,,,,,,,,,,,,,,,
,3923199105.09121,300.004486083984,59999.66796875,,,,,,1.835858E-05,0.0005145207,,5.24288,0.0001,0,,,,,,,,,1,,,,,,,,,,,,,,,,,,,,,,,33557376,0,1,4,3,,,,,,,,,,,,,,,,
,3923199105.1872,300.004486083984,59999.66796875,,,,,,6.639471E-06,-0.0001029041,,5.24288,0.0001,0,,,,,,,,,1,,,,,,,,,,,,,,,,,,,,,,,33557376,0,1,4,3,,,,,,,,,,,,,,,,
,3923199105.28321,300.004486083984,59999.66796875,,,,,,-5.076245E-06,0.0006174249,,5.24288,0.0001,0,,,,,,,,,1,,,,,,,,,,,,,,,,,,,,,,,33557376,0,1,4,3,,,,,,,,,,,,,,,,
,3923199105.3792,300.004486083984,59999.66796875,,,,,,-1.679535E-05,-0.0009261373,,5.24288,0.0001,0,,,,,,,,,1,,,,,,,,,,,,,,,,,,,,,,,33557376,0,1,4,3,,,,,,,,,,,,,,,,
,3923199105.4752,300.004486083984,59999.66796875,,,,,,-2.851446E-05,-0.002949919,,5.24288,0.0001,0,,,,,,,,,1,,,,,,,,,,,,,,,,,,,,,,,33557376,0,1,4,3,,,,,,,,,,,,,,,,
,3923199105.57121,300.004486083984,59999.66796875,,,,,,-4.023357E-05,-0.003841755,,5.24288,0.0001,0,,,,,,,,,1,,,,,,,,,,,,,,,,,,,,,,,33557376,0,1,4,3,,,,,,,,,,,,,,,,
,3923199105.6672,300.004486083984,59999.66796875,,,,,,-5.195267E-05,-0.003704549,,5.24288,0.0001,0,,,,,,,,,1,,,,,,,,,,,,,,,,,,,,,,,33557376,0,1,4,3,,,,,,,,,,,,,,,,
,3923199105.76321,300.004486083984,59999.66796875,,,,,,-6.367178E-05,-0.004596385,,5.24288,0.0001,0,,,,,,,,,1,,,,,,,,,,,,,,,,,,,,,,,33557376,0,1,4,3,,,,,,,,,,,,,,,,
,3923199105.8592,300.004486083984,59999.66796875,,,,,,-7.539089E-05,-0.005351015,,5.24288,0.0001,0,,,,,,,,,1,,,,,,,,,,,,,,,,,,,,,,,33557376,0,1,4,3,,,,,,,,,,,,,,,,
,3923199105.95521,300.004486083984,59999.66796875,,,,,,-8.711E-05,-0.005659728,,5.24288,0.0001,0,,,,,,,,,1,,,,,,,,,,,,,,,,,,,,,,,33557376,0,1,4,3,,,,,,,,,,,,,,,,
,3923199106.0512,300.004486083984,59999.66796875,,,,,,-9.882911E-05,-0.006791674,,5.24288,0.0001,0,,,,,,,,,1,,,,,,,,,,,,,,,,,,,,,,,33557376,0,1,4,3,,,,,,,,,,,,,,,,
,3923199106.1472,300.004486083984,59999.66796875,,,,,,-8.945314E-05,-0.006757372,,5.24288,0.0001,0,,,,,,,,,1,,,,,,,,,,,,,,,,,,,,,,,33557376,0,1,4,3,,,,,,,,,,,,,,,,
,3923199106.24321,300.004486083984,59999.66796875,,,,,,-7.773403E-05,-0.005865536,,5.24288,0.0001,0,,,,,,,,,1,,,,,,,,,,,,,,,,,,,,,,,33557376,0,1,4,3,,,,,,,,,,,,,,,,
,3923199106.3392,300.004486083984,59999.66796875,,,,,,-6.601492E-05,-0.004150467,,5.24288,0.0001,0,,,,,,,,,1,,,,,,,,,,,,,,,,,,,,,,,33557376,0,1,4,3,,,,,,,,,,,,,,,,
,3923199106.43521,300.004486083984,59999.66796875,,,,,,-5.429582E-05,-0.003841755,,5.24288,0.0001,0,,,,,,,,,1,,,,,,,,,,,,,,,,,,,,,,,33557376,0,1,4,3,,,,,,,,,,,,,,,,
,3923199106.5312,300.004486083984,59999.66796875,,,,,,-4.257671E-05,-0.002744111,,5.24288,0.0001,0,,,,,,,,,1,,,,,,,,,,,,,,,,,,,,,,,33557376,0,1,4,3,,,,,,,,,,,,,,,,
,3923199106.6272,300.004486083984,59999.66796875,,,,,,-3.08576E-05,-0.002435398,,5.24288,0.0001,0,,,,,,,,,1,,,,,,,,,,,,,,,,,,,,,,,33557376,0,1,4,3,,,,,,,,,,,,,,,,
,3923199106.7232,300.004486083984,59999.66796875,,,,,,-1.91385E-05,-0.0004802193,,5.24288,0.0001,0,,,,,,,,,1,,,,,,,,,,,,,,,,,,,,,,,33557376,0,1,4,3,,,,,,,,,,,,,,,,
,3923199106.8192,300.004486083984,59999.66796875,,,,,,-7.419389E-06,-0.00123485,,5.24288,0.0001,0,,,,,,,,,1,,,,,,,,,,,,,,,,,,,,,,,33557376,0,1,4,3,,,,,,,,,,,,,,,,
,3923199177.64945,300.004364013672,69999.828125,,,,,,4.686287E-06,0.0002401097,,5.24288,0.0001,0,,,,,,,,,1,,,,,,,,,,,,,,,,,,,,,,,33557376,0,1,4,3,,,,,,,,,,,,,,,,
,3923199177.74545,300.004364013672,69999.828125,,,,,,1.640539E-05,0.001097644,,5.24288,0.0001,0,,,,,,,,,1,,,,,,,,,,,,,,,,,,,,,,,33557376,0,1,4,3,,,,,,,,,,,,,,,,
,3923199177.84145,300.004364013672,69999.828125,,,,,,2.81245E-05,0.001509261,,5.24288,0.0001,0,,,,,,,,,1,,,,,,,,,,,,,,,,,,,,,,,33557376,0,1,4,3,,,,,,,,,,,,,,,,
,3923199177.93745,300.004364013672,69999.828125,,,,,,3.984361E-05,0.002847015,,5.24288,0.0001,0,,,,,,,,,1,,,,,,,,,,,,,,,,,,,,,,,33557376,0,1,4,3,,,,,,,,,,,,,,,,
,3923199178.03345,300.004364013672,69999.828125,,,,,,5.156271E-05,0.003395837,,5.24288,0.0001,0,,,,,,,,,1,,,,,,,,,,,,,,,,,,,,,,,33557376,0,1,4,3,,,,,,,,,,,,,,,,
,3923199178.12945,300.004364013672,69999.828125,,,,,,6.328183E-05,0.003910358,,5.24288,0.0001,0,,,,,,,,,1,,,,,,,,,,,,,,,,,,,,,,,33557376,0,1,4,3,,,,,,,,,,,,,,,,
,3923199178.22545,300.004364013672,69999.828125,,,,,,7.500093E-05,0.0049737,,5.24288,0.0001,0,,,,,,,,,1,,,,,,,,,,,,,,,,,,,,,,,33557376,0,1,4,3,,,,,,,,,,,,,,,,
,3923199178.32145,300.004364013672,69999.828125,,,,,,8.672004E-05,0.005419618,,5.24288,0.0001,0,,,,,,,,,1,,,,,,,,,,,,,,,,,,,,,,,33557376,0,1,4,3,,,,,,,,,,,,,,,,
,3923199178.41745,300.004364013672,69999.828125,,,,,,9.843914E-05,0.007066085,,5.24288,0.0001,0,,,,,,,,,1,,,,,,,,,,,,,,,,,,,,,,,33557376,0,1,4,3,,,,,,,,,,,,,,,,
,3923199178.51345,300.004364013672,69999.828125,,,,,,8.984649E-05,0.005625427,,5.24288,0.0001,0,,,,,,,,,1,,,,,,,,,,,,,,,,,,,,,,,33557376,0,1,4,3,,,,,,,,,,,,,,,,
,3923199178.60945,300.004364013672,69999.828125,,,,,,7.812738E-05,0.005762632,,5.24288,0.0001,0,,,,,,,,,1,,,,,,,,,,,,,,,,,,,,,,,33557376,0,1,4,3,,,,,,,,,,,,,,,,
,3923199178.70545,300.004364013672,69999.828125,,,,,,6.640828E-05,0.004253371,,5.24288,0.0001,0,,,,,,,,,1,,,,,,,,,,,,,,,,,,,,,,,33557376,0,1,4,3,,,,,,,,,,,,,,,,
,3923199178.80145,300.004364013672,69999.828125,,,,,,5.468917E-05,0.002949919,,5.24288,0.0001,0,,,,,,,,,1,,,,,,,,,,,,,,,,,,,,,,,33557376,0,1,4,3,,,,,,,,,,,,,,,,
,3923199178.89745,300.004364013672,69999.828125,,,,,,4.297006E-05,0.00397896,,5.24288,0.0001,0,,,,,,,,,1,,,,,,,,,,,,,,,,,,,,,,,33557376,0,1,4,3,,,,,,,,,,,,,,,,
,3923199178.99345,300.004364013672,69999.828125,,,,,,3.125095E-05,0.001406357,,5.24288,0.0001,0,,,,,,,,,1,,,,,,,,,,,,,,,,,,,,,,,33557376,0,1,4,3,,,,,,,,,,,,,,,,
,3923199179.08945,300.004364013672,69999.828125,,,,,,1.953185E-05,0.0007546304,,5.24288,0.0001,0,,,,,,,,,1,,,,,,,,,,,,,,,,,,,,,,,33557376,0,1,4,3,,,,,,,,,,,,,,,,
,3923199179.18545,300.004364013672,69999.828125,,,,,,7.812739E-06,-0.0002058083,,5.24288,0.0001,0,,,,,,,,,1,,,,,,,,,,,,,,,,,,,,,,,33557376,0,1,4,3,,,,,,,,,,,,,,,,
,3923199179.28145,300.004364013672,69999.828125,,,,,,-3.906369E-06,-0.0008232332,,5.24288,0.0001,0,,,,,,,,,1,,,,,,,,,,,,,,,,,,,,,,,33557376,0,1,4,3,,,,,,,,,,,,,,,,
,3923199179.37745,300.004364013672,69999.828125,,,,,,-1.562548E-05,-0.001372055,,5.24288,0.0001,0,,,,,,,,,1,,,,,,,,,,,,,,,,,,,,,,,33557376,0,1,4,3,,,,,,,,,,,,,,,,
,3923199179.47345,300.004364013672,69999.828125,,,,,,-2.734458E-05,-0.00174937,,5.24288,0.0001,0,,,,,,,,,1,,,,,,,,,,,,,,,,,,,,,,,33557376,0,1,4,3,,,,,,,,,,,,,,,,
,3923199179.56945,300.004364013672,69999.828125,,,,,,-3.906369E-05,-0.00298422,,5.24288,0.0001,0,,,,,,,,,1,,,,,,,,,,,,,,,,,,,,,,,33557376,0,1,4,3,,,,,,,,,,,,,,,,
,3923199179.66545,300.004364013672,69999.828125,,,,,,-5.07828E-05,-0.00346444,,5.24288,0.0001,0,,,,,,,,,1,,,,,,,,,,,,,,,,,,,,,,,33557376,0,1,4,3,,,,,,,,,,,,,,,,
,3923199179.76145,300.004364013672,69999.828125,,,,,,-6.250191E-05,-0.004527783,,5.24288,0.0001,0,,,,,,,,,1,,,,,,,,,,,,,,,,,,,,,,,33557376,0,1,4,3,,,,,,,,,,,,,,,,
,3923199179.85745,300.004364013672,69999.828125,,,,,,-7.422101E-05,-0.005282413,,5.24288,0.0001,0,,,,,,,,,1,,,,,,,,,,,,,,,,,,,,,,,33557376,0,1,4,3,,,,,,,,,,,,,,,,
,3923199179.95345,300.004364013672,69999.828125,,,,,,-8.594012E-05,-0.006688769,,5.24288,0.0001,0,,,,,,,,,1,,,,,,,,,,,,,,,,,,,,,,,33557376,0,1,4,3,,,,,,,,,,,,,,,,
,3923199180.04945,300.004364013672,69999.828125,,,,,,-9.765923E-05,-0.007923619,,5.24288,0.0001,0,,,,,,,,,1,,,,,,,,,,,,,,,,,,,,,,,33557376,0,1,4,3,,,,,,,,,,,,,,,,
,3923199180.14545,300.004364013672,69999.828125,,,,,,-9.062641E-05,-0.005934139,,5.24288,0.0001,0,,,,,,,,,1,,,,,,,,,,,,,,,,,,,,,,,33557376,0,1,4,3,,,,,,,,,,,,,,,,
,3923199180.24145,300.004364013672,69999.828125,,,,,,-7.89073E-05,-0.004150467,,5.24288,0.0001,0,,,,,,,,,1,,,,,,,,,,,,,,,,,,,,,,,33557376,0,1,4,3,,,,,,,,,,,,,,,,
,3923199180.33745,300.004364013672,69999.828125,,,,,,-6.718819E-05,-0.005110906,,5.24288,0.0001,0,,,,,,,,,1,,,,,,,,,,,,,,,,,,,,,,,33557376,0,1,4,3,,,,,,,,,,,,,,,,
,3923199180.43345,300.004364013672,69999.828125,,,,,,-5.546909E-05,-0.004664988,,5.24288,0.0001,0,,,,,,,,,1,,,,,,,,,,,,,,,,,,,,,,,33557376,0,1,4,3,,,,,,,,,,,,,,,,
,3923199180.52945,300.004364013672,69999.828125,,,,,,-4.374998E-05,-0.004562084,,5.24288,0.0001,0,,,,,,,,,1,,,,,,,,,,,,,,,,,,,,,,,33557376,0,1,4,3,,,,,,,,,,,,,,,,
,3923199180.62545,300.004364013672,69999.828125,,,,,,-3.203087E-05,-0.002023781,,5.24288,0.0001,0,,,,,,,,,1,,,,,,,,,,,,,,,,,,,,,,,33557376,0,1,4,3,,,,,,,,,,,,,,,,
,3923199180.72145,300.004364013672,69999.828125,,,,,,-2.031176E-05,-0.001920877,,5.24288,0.0001,0,,,,,,,,,1,,,,,,,,,,,,,,,,,,,,,,,33557376,0,1,4,3,,,,,,,,,,,,,,,,
,3923199180.81745,300.004364013672,69999.828125,,,,,,-8.592656E-06,-0.001131946,,5.24288,0.0001,0,,,,,,,,,1,,,,,,,,,,,,,,,,,,,,,,,33557376,0,1,4,3,,,,,,,,,,,,,,,,
,3923199252.11804,300.002807617188,79999.59375,,,,,,3.513019E-06,0.0005488221,,5.24288,0.0001,0,,,,,,,,,1,,,,,,,,,,,,,,,,,,,,,,,33557376,0,1,4,3,,,,,,,,,,,,,,,,
,3923199252.21404,300.002807617188,79999.59375,,,,,,1.523213E-05,0.0002744111,,5.24288,0.0001,0,,,,,,,,,1,,,,,,,,,,,,,,,,,,,,,,,33557376,0,1,4,3,,,,,,,,,,,,,,,,
,3923199252.31004,300.002807617188,79999.59375,,,,,,2.695123E-05,0.002195288,,5.24288,0.0001,0,,,,,,,,,1,,,,,,,,,,,,,,,,,,,,,,,33557376,0,1,4,3,,,,,,,,,,,,,,,,
,3923199252.40604,300.002807617188,79999.59375,,,,,,3.867034E-05,0.002744111,,5.24288,0.0001,0,,,,,,,,,1,,,,,,,,,,,,,,,,,,,,,,,33557376,0,1,4,3,,,,,,,,,,,,,,,,
,3923199252.50204,300.002807617188,79999.59375,,,,,,5.038945E-05,0.003430138,,5.24288,0.0001,0,,,,,,,,,1,,,,,,,,,,,,,,,,,,,,,,,33557376,0,1,4,3,,,,,,,,,,,,,,,,
,3923199252.59804,300.002807617188,79999.59375,,,,,,6.210856E-05,0.004527783,,5.24288,0.0001,0,,,,,,,,,1,,,,,,,,,,,,,,,,,,,,,,,33557376,0,1,4,3,,,,,,,,,,,,,,,,
,3923199252.69404,300.002807617188,79999.59375,,,,,,7.382766E-05,0.004939399,,5.24288,0.0001,0,,,,,,,,,1,,,,,,,,,,,,,,,,,,,,,,,33557376,0,1,4,3,,,,,,,,,,,,,,,,
,3923199252.79004,300.002807617188,79999.59375,,,,,,8.554677E-05,0.005042303,,5.24288,0.0001,0,,,,,,,,,1,,,,,,,,,,,,,,,,,,,,,,,33557376,0,1,4,3,,,,,,,,,,,,,,,,
,3923199252.88604,300.002807617188,79999.59375,,,,,,9.726588E-05,0.00596844,,5.24288,0.0001,0,,,,,,,,,1,,,,,,,,,,,,,,,,,,,,,,,33557376,0,1,4,3,,,,,,,,,,,,,,,,
,3923199252.98204,300.002807617188,79999.59375,,,,,,9.101637E-05,0.006997482,,5.24288,0.0001,0,,,,,,,,,1,,,,,,,,,,,,,,,,,,,,,,,33557376,0,1,4,3,,,,,,,,,,,,,,,,
,3923199253.07804,300.002807617188,79999.59375,,,,,,7.929726E-05,0.005694029,,5.24288,0.0001,0,,,,,,,,,1,,,,,,,,,,,,,,,,,,,,,,,33557376,0,1,4,3,,,,,,,,,,,,,,,,
,3923199253.17404,300.002807617188,79999.59375,,,,,,6.757815E-05,0.003670248,,5.24288,0.0001,0,,,,,,,,,1,,,,,,,,,,,,,,,,,,,,,,,33557376,0,1,4,3,,,,,,,,,,,,,,,,
,3923199253.27004,300.002807617188,79999.59375,,,,,,5.585904E-05,0.003018522,,5.24288,0.0001,0,,,,,,,,,1,,,,,,,,,,,,,,,,,,,,,,,33557376,0,1,4,3,,,,,,,,,,,,,,,,
,3923199253.36604,300.002807617188,79999.59375,,,,,,4.413994E-05,0.002606905,,5.24288,0.0001,0,,,,,,,,,1,,,,,,,,,,,,,,,,,,,,,,,33557376,0,1,4,3,,,,,,,,,,,,,,,,
,3923199253.46204,300.002807617188,79999.59375,,,,,,3.242083E-05,0.001406357,,5.24288,0.0001,0,,,,,,,,,1,,,,,,,,,,,,,,,,,,,,,,,33557376,0,1,4,3,,,,,,,,,,,,,,,,
,3923199253.55804,300.002807617188,79999.59375,,,,,,2.070172E-05,0.001097644,,5.24288,0.0001,0,,,,,,,,,1,,,,,,,,,,,,,,,,,,,,,,,33557376,0,1,4,3,,,,,,,,,,,,,,,,
,3923199253.65404,300.002807617188,79999.59375,,,,,,8.982614E-06,0.001200548,,5.24288,0.0001,0,,,,,,,,,1,,,,,,,,,,,,,,,,,,,,,,,33557376,0,1,4,3,,,,,,,,,,,,,,,,
,3923199253.75004,300.002807617188,79999.59375,,,,,,-2.733102E-06,-0.0006174249,,5.24288,0.0001,0,,,,,,,,,1,,,,,,,,,,,,,,,,,,,,,,,33557376,0,1,4,3,,,,,,,,,,,,,,,,
,3923199253.84604,300.002807617188,79999.59375,,,,,,-1.445221E-05,-0.002058083,,5.24288,0.0001,0,,,,,,,,,1,,,,,,,,,,,,,,,,,,,,,,,33557376,0,1,4,3,,,,,,,,,,,,,,,,
,3923199253.94204,300.002807617188,79999.59375,,,,,,-2.617132E-05,-0.002092384,,5.24288,0.0001,0,,,,,,,,,1,,,,,,,,,,,,,,,,,,,,,,,33557376,0,1,4,3,,,,,,,,,,,,,,,,
,3923199254.03804,300.002807617188,79999.59375,,,,,,-3.789042E-05,-0.002915618,,5.24288,0.0001,0,,,,,,,,,1,,,,,,,,,,,,,,,,,,,,,,,33557376,0,1,4,3,,,,,,,,,,,,,,,,
,3923199254.13404,300.002807617188,79999.59375,,,,,,-4.960953E-05,-0.003704549,,5.24288,0.0001,0,,,,,,,,,1,,,,,,,,,,,,,,,,,,,,,,,33557376,0,1,4,3,,,,,,,,,,,,,,,,
,3923199254.23004,300.002807617188,79999.59375,,,,,,-6.132864E-05,-0.004905098,,5.24288,0.0001,0,,,,,,,,,1,,,,,,,,,,,,,,,,,,,,,,,33557376,0,1,4,3,,,,,,,,,,,,,,,,
,3923199254.32604,300.002807617188,79999.59375,,,,,,-7.304775E-05,-0.004356275,,5.24288,0.0001,0,,,,,,,,,1,,,,,,,,,,,,,,,,,,,,,,,33557376,0,1,4,3,,,,,,,,,,,,,,,,
,3923199254.42204,300.002807617188,79999.59375,,,,,,-8.476686E-05,-0.006380057,,5.24288,0.0001,0,,,,,,,,,1,,,,,,,,,,,,,,,,,,,,,,,33557376,0,1,4,3,,,,,,,,,,,,,,,,
,3923199254.51804,300.002807617188,79999.59375,,,,,,-9.648596E-05,-0.00644866,,5.24288,0.0001,0,,,,,,,,,1,,,,,,,,,,,,,,,,,,,,,,,33557376,0,1,4,3,,,,,,,,,,,,,,,,
,3923199254.61404,300.002807617188,79999.59375,,,,,,-9.179967E-05,-0.007168989,,5.24288,0.0001,0,,,,,,,,,1,,,,,,,,,,,,,,,,,,,,,,,33557376,0,1,4,3,,,,,,,,,,,,,,,,
,3923199254.71004,300.002807617188,79999.59375,,,,,,-8.008056E-05,-0.006791674,,5.24288,0.0001,0,,,,,,,,,1,,,,,,,,,,,,,,,,,,,,,,,33557376,0,1,4,3,,,,,,,,,,,,,,,,
,3923199254.80604,300.002807617188,79999.59375,,,,,,-6.836146E-05,-0.003944659,,5.24288,0.0001,0,,,,,,,,,1,,,,,,,,,,,,,,,,,,,,,,,33557376,0,1,4,3,,,,,,,,,,,,,,,,
,3923199254.90204,300.002807617188,79999.59375,,,,,,-5.664235E-05,-0.003567344,,5.24288,0.0001,0,,,,,,,,,1,,,,,,,,,,,,,,,,,,,,,,,33557376,0,1,4,3,,,,,,,,,,,,,,,,
,3923199254.99804,300.002807617188,79999.59375,,,,,,-4.492325E-05,-0.004013262,,5.24288,0.0001,0,,,,,,,,,1,,,,,,,,,,,,,,,,,,,,,,,33557376,0,1,4,3,,,,,,,,,,,,,,,,
,3923199255.09404,300.002807617188,79999.59375,,,,,,-3.320414E-05,-0.002812713,,5.24288,0.0001,0,,,,,,,,,1,,,,,,,,,,,,,,,,,,,,,,,33557376,0,1,4,3,,,,,,,,,,,,,,,,
,3923199255.19004,300.002807617188,79999.59375,,,,,,-2.148503E-05,-0.00174937,,5.24288,0.0001,0,,,,,,,,,1,,,,,,,,,,,,,,,,,,,,,,,33557376,0,1,4,3,,,,,,,,,,,,,,,,
,3923199255.28604,300.002807617188,79999.59375,,,,,,-9.765923E-06,-0.001646466,,5.24288,0.0001,0,,,,,,,,,1,,,,,,,,,,,,,,,,,,,,,,,33557376,0,1,4,3,,,,,,,,,,,,,,,,
,3923199326.56042,300.001403808594,89999.703125,,,,,,2.343143E-06,0.0002401097,,5.24288,0.0001,0,,,,,,,,,1,,,,,,,,,,,,,,,,,,,,,,,33557376,0,1,4,3,,,,,,,,,,,,,,,,
,3923199326.65642,300.001403808594,89999.703125,,,,,,1.406225E-05,0.0002744111,,5.24288,0.0001,0,,,,,,,,,1,,,,,,,,,,,,,,,,,,,,,,,33557376,0,1,4,3,,,,,,,,,,,,,,,,
,3923199326.75242,300.001403808594,89999.703125,,,,,,2.578136E-05,0.001543562,,5.24288,0.0001,0,,,,,,,,,1,,,,,,,,,,,,,,,,,,,,,,,33557376,0,1,4,3,,,,,,,,,,,,,,,,
,3923199326.84842,300.001403808594,89999.703125,,,,,,3.750046E-05,0.002195288,,5.24288,0.0001,0,,,,,,,,,1,,,,,,,,,,,,,,,,,,,,,,,33557376,0,1,4,3,,,,,,,,,,,,,,,,
,3923199326.94442,300.001403808594,89999.703125,,,,,,4.921957E-05,0.003533042,,5.24288,0.0001,0,,,,,,,,,1,,,,,,,,,,,,,,,,,,,,,,,33557376,0,1,4,3,,,,,,,,,,,,,,,,
,3923199327.04042,300.001403808594,89999.703125,,,,,,6.093868E-05,0.003258631,,5.24288,0.0001,0,,,,,,,,,1,,,,,,,,,,,,,,,,,,,,,,,33557376,0,1,4,3,,,,,,,,,,,,,,,,
,3923199327.13642,300.001403808594,89999.703125,,,,,,7.265779E-05,0.005316714,,5.24288,0.0001,0,,,,,,,,,1,,,,,,,,,,,,,,,,,,,,,,,33557376,0,1,4,3,,,,,,,,,,,,,,,,
,3923199327.23242,300.001403808594,89999.703125,,,,,,8.437689E-05,0.005728331,,5.24288,0.0001,0,,,,,,,,,1,,,,,,,,,,,,,,,,,,,,,,,33557376,0,1,4,3,,,,,,,,,,,,,,,,
,3923199327.32842,300.001403808594,89999.703125,,,,,,9.6096E-05,0.006002742,,5.24288,0.0001,0,,,,,,,,,1,,,,,,,,,,,,,,,,,,,,,,,33557376,0,1,4,3,,,,,,,,,,,,,,,,
,3923199327.42442,300.001403808594,89999.703125,,,,,,9.218964E-05,0.00596844,,5.24288,0.0001,0,,,,,,,,,1,,,,,,,,,,,,,,,,,,,,,,,33557376,0,1,4,3,,,,,,,,,,,,,,,,
,3923199327.52042,300.001403808594,89999.703125,,,,,,8.047053E-05,0.005110906,,5.24288,0.0001,0,,,,,,,,,1,,,,,,,,,,,,,,,,,,,,,,,33557376,0,1,4,3,,,,,,,,,,,,,,,,
,3923199327.61642,300.001403808594,89999.703125,,,,,,6.875142E-05,0.005831235,,5.24288,0.0001,0,,,,,,,,,1,,,,,,,,,,,,,,,,,,,,,,,33557376,0,1,4,3,,,,,,,,,,,,,,,,
,3923199327.71242,300.001403808594,89999.703125,,,,,,5.703231E-05,0.003601645,,5.24288,0.0001,0,,,,,,,,,1,,,,,,,,,,,,,,,,,,,,,,,33557376,0,1,4,3,,,,,,,,,,,,,,,,
,3923199327.80842,300.001403808594,89999.703125,,,,,,4.531321E-05,0.0024697,,5.24288,0.0001,0,,,,,,,,,1,,,,,,,,,,,,,,,,,,,,,,,33557376,0,1,4,3,,,,,,,,,,,,,,,,
,3923199327.90442,300.001403808594,89999.703125,,,,,,3.35941E-05,0.001509261,,5.24288,0.0001,0,,,,,,,,,1,,,,,,,,,,,,,,,,,,,,,,,33557376,0,1,4,3,,,,,,,,,,,,,,,,
,3923199328.00042,300.001403808594,89999.703125,,,,,,2.187499E-05,0.0008232332,,5.24288,0.0001,0,,,,,,,,,1,,,,,,,,,,,,,,,,,,,,,,,33557376,0,1,4,3,,,,,,,,,,,,,,,,
,3923199328.09642,300.001403808594,89999.703125,,,,,,1.015588E-05,-0.0006174249,,5.24288,0.0001,0,,,,,,,,,1,,,,,,,,,,,,,,,,,,,,,,,33557376,0,1,4,3,,,,,,,,,,,,,,,,
,3923199328.19242,300.001403808594,89999.703125,,,,,,-1.559835E-06,-0.0001029041,,5.24288,0.0001,0,,,,,,,,,1,,,,,,,,,,,,,,,,,,,,,,,33557376,0,1,4,3,,,,,,,,,,,,,,,,
,3923199328.28842,300.001403808594,89999.703125,,,,,,-1.327894E-05,0.0004802193,,5.24288,0.0001,0,,,,,,,,,1,,,,,,,,,,,,,,,,,,,,,,,33557376,0,1,4,3,,,,,,,,,,,,,,,,
,3923199328.38442,300.001403808594,89999.703125,,,,,,-2.499805E-05,-0.001852275,,5.24288,0.0001,0,,,,,,,,,1,,,,,,,,,,,,,,,,,,,,,,,33557376,0,1,4,3,,,,,,,,,,,,,,,,
,3923199328.48042,300.001403808594,89999.703125,,,,,,-3.671716E-05,-0.002847015,,5.24288,0.0001,0,,,,,,,,,1,,,,,,,,,,,,,,,,,,,,,,,33557376,0,1,4,3,,,,,,,,,,,,,,,,
,3923199328.57642,300.001403808594,89999.703125,,,,,,-4.843626E-05,-0.003533042,,5.24288,0.0001,0,,,,,,,,,1,,,,,,,,,,,,,,,,,,,,,,,33557376,0,1,4,3,,,,,,,,,,,,,,,,
,3923199328.67242,300.001403808594,89999.703125,,,,,,-6.015537E-05,-0.004939399,,5.24288,0.0001,0,,,,,,,,,1,,,,,,,,,,,,,,,,,,,,,,,33557376,0,1,4,3,,,,,,,,,,,,,,,,
,3923199328.76842,300.001403808594,89999.703125,,,,,,-7.187448E-05,-0.005008002,,5.24288,0.0001,0,,,,,,,,,1,,,,,,,,,,,,,,,,,,,,,,,33557376,0,1,4,3,,,,,,,,,,,,,,,,
,3923199328.86442,300.001403808594,89999.703125,,,,,,-8.359359E-05,-0.005762632,,5.24288,0.0001,0,,,,,,,,,1,,,,,,,,,,,,,,,,,,,,,,,33557376,0,1,4,3,,,,,,,,,,,,,,,,
,3923199328.96042,300.001403808594,89999.703125,,,,,,-9.531269E-05,-0.007237592,,5.24288,0.0001,0,,,,,,,,,1,,,,,,,,,,,,,,,,,,,,,,,33557376,0,1,4,3,,,,,,,,,,,,,,,,
,3923199329.05642,300.001403808594,89999.703125,,,,,,-9.296955E-05,-0.007306194,,5.24288,0.0001,0,,,,,,,,,1,,,,,,,,,,,,,,,,,,,,,,,33557376,0,1,4,3,,,,,,,,,,,,,,,,
,3923199329.15242,300.001403808594,89999.703125,,,,,,-8.125044E-05,-0.006654468,,5.24288,0.0001,0,,,,,,,,,1,,,,,,,,,,,,,,,,,,,,,,,33557376,0,1,4,3,,,,,,,,,,,,,,,,
,3923199329.24842,300.001403808594,89999.703125,,,,,,-6.953134E-05,-0.004459179,,5.24288,0.0001,0,,,,,,,,,1,,,,,,,,,,,,,,,,,,,,,,,33557376,0,1,4,3,,,,,,,,,,,,,,,,
,3923199329.34442,300.001403808594,89999.703125,,,,,,-5.781223E-05,-0.004116166,,5.24288,0.0001,0,,,,,,,,,1,,,,,,,,,,,,,,,,,,,,,,,33557376,0,1,4,3,,,,,,,,,,,,,,,,
,3923199329.44042,300.001403808594,89999.703125,,,,,,-4.609312E-05,-0.003773152,,5.24288,0.0001,0,,,,,,,,,1,,,,,,,,,,,,,,,,,,,,,,,33557376,0,1,4,3,,,,,,,,,,,,,,,,
,3923199329.53642,300.001403808594,89999.703125,,,,,,-3.437401E-05,-0.002847015,,5.24288,0.0001,0,,,,,,,,,1,,,,,,,,,,,,,,,,,,,,,,,33557376,0,1,4,3,,,,,,,,,,,,,,,,
,3923199329.63242,300.001403808594,89999.703125,,,,,,-2.265491E-05,-0.001372055,,5.24288,0.0001,0,,,,,,,,,1,,,,,,,,,,,,,,,,,,,,,,,33557376,0,1,4,3,,,,,,,,,,,,,,,,
,3923199329.72842,300.001403808594,89999.703125,,,,,,-1.09358E-05,-0.0008232332,,5.24288,0.0001,0,,,,,,,,,1,,,,,,,,,,,,,,,,,,,,,,,33557376,0,1,4,3,,,,,,,,,,,,,,,,
,3923199329.81162,300.001403808594,89999.703125,,,,,,-7.799175E-07,-0.001131946,,5.24288,0.0001,0,,,,,,,,,1,,,,,,,,,,,,,,,,,,,,,,,33557376,0,1,4,3,,,,,,,,,,,,,,,,